Workbook

Sheet SKU-SHERINK
A1: PRODUTO | B1: DESCRIÇÃO | D1: PRODUTO | E1: DESCRIÇÃO | G1: MELI_01
A2: 32136 | B2: Óleo SOS Cachos Óleo de Coco 42ml | D2: 32060 | E2: CREME PARA PENTEAR CONDICIONADOR DEFINIÇÃO NATURAL 1KG | G2: 32060
A3: 32137 | B3: Óleo de Tratamento SOS Cachos Super Óleos 42ml | D3: 33271 | E3: CREME PARA PENTEAR CACHOS OSTENTAÇÃO 1KG | G3: 95679
A4: 32202 | B4: Óleo de Tratamento SOS Cachos Super Óleos 100ml | D4: 95679 | E4: #TODECACHO GELATINA CONDICIONANTE SUPER DEFINICAO 1KG | G4: 33107
A5: 32249 | B5: Óleo SOS Cachos 10 em 1 Multibenefícios 100ml | D5: 34988 | E5: SOS HIDRATACAO MASCARA CONDICIONANTE OLEO DE RICINO 1KG | G5: 33271
A6: 32259 | B6: Óleo de Tratamento SOS Cachos 10 em 1 Multibenefícios 42ml | D6: 33107 | E6: #TODECACHO GELATINA DEFINIÇÃO NATURAL 550G | G6: 32247
A7: 32443 | B7: Óleo de Tratamento Multifuncional Meu Liso Demais 60ml | D7: 33272 | E7: CREME PARA PENTEAR XO POROSIDADE! DEFINIÇÃO & SELAGEM MÁXIMA 1KG | G7: 34936
A8: 32444 | B8: Óleo de Tratamento Multifuncional Meu Liso Muito + Liso 60ml | D8: 34936 | E8: SOS HIDRATACAO MASCARA CONDICIONANTE AZEITE DE OLIVA 1KG | G8: 95701
A9: 32624 | B9: Óleo Reparador Melancia Cachos dos Sonhos Multy Poderosos 50ml | D9: 32209 | E9: SOS CACHOS GELATINA CONDICIONANTE KIDS HIDRATAÇÃO 400GR | G9: 30851
A10: 32625 | B10: Óleo de Tratamento Banana Cachos dos Sonhos Multy Maravilhas 50ml | D10: 34932 | E10: SOS HIDRATACAO MASCARA CONDICIONANTE QUERATINA E COLAGENO 1KG | G10: 32200
A11: 32626 | B11: Óleo Reparador Morango Cachos dos Sonhos Multy Extraordinário 50ml | D11: 95109 | E11: MASCARA CONDICIONANTE KIDS HIDRATAÇÃO CACHOS SOS 500GR | G11: 34682
A12: 32632 | B12: Óleo Trata e Finaliza SOS Cachos De Repente Pronta 42ml | D12: 32247 | E12: CREME PARA PENTEAR CONDICIONADOR DEFINIÇÃO EXTRAORDINÁRIA 1KG | G12: 95004
A13: 32892 | B13: Óleo Reparador Uva Cachos dos Sonhos Multy Irresistível 50ml | D13: 95076 | E13: SL CREME PENTEAR CONDICIONADOR DEFINICAO INTENSA 1KG | G13: 32199
... A21: 33644 | B21: SALON LINE ÓLEO DEFINIÇÃO NATURAL CONDICIONANTE 50ML | D21: 34530 | E21: SOS CACHOS ATIVADOR CONDICIONADOR DE CACHOS ARGININA 500G | G21: 31716
D22: 30745 | E22: SL CREME PENTEAR CONDICIONADOR AZEITE DE OLIVA 1KG | G22: 32446
D23: 95556 | E23: SL CREME PENTEAR CONDICIONADOR SUPER OLEOS 1KG | G23: 33583
D24: 32619 | E24: CACHOS DOS SONHOS CREME DE TRATAMENTO MULTY MILAGRES ANTIPOROSIDADE 1KG
D25: 32884 | E25: #TODECACHINHO KIDS GELATINA DEFINIDORA CONDICIONANTE (AÇAÍ) 550G
D26: 30851 | E26: #TODECACHO MASCARA CONDICIONANTE MATIZ MARSALA ROXO MAIONESE 500GR
D27: 95355 | E27: #TODECACHO MASCARA CONDICIONANTE MATIZ VERMELHA MAIONESE 500GR
D28: 33584 | E28: CREME PARA PENTEAR CONDICIONANTE DEFINIÇÃO A PROVA 1KG
D29: 32200 | E29: SOS CACHOS CREME PARA PENTEAR GEL CREME CONDICIONADOR SUPER ÓLEOS 1KG
D30: 33583 | E30: CREME PARA PENTEAR CONDICIONANTE DEFINIÇÃO CACHOS DE SEREIA 1 KG
D31: 33631 | E31: CREME PARA PENTEAR CONDICIONANTE DEFINIÇÃO COLA 1KG
D32: 95119 | E32: #TODECACHO GELATINA CONDICIONANTE SUPER DEFINICAO 550GR
D33: 32199 | E33: SOS CACHOS GELATINA CONDICIONANTE NUTRITIVA ATIVADORA DE CACHOS SUPER ÓLEOS 400GR
D34: 34437 | E34: Ativador de Cachos SOS Cachos Óleo de Manga Salon Line 500g
D35: 32616 | E35: CREME PARA PENTEAR DEFINIÇÃO NUTRITIVA CONDICIONADOR 1KG
... D97: 33321 | E97: CACHOS DOS SONHOS - CREME CONDICIONADOR DE TRATAMENTO MULTY PINK LEMONADE 1KG

Sheet KIT MELI
A1: SKU
A2: 95269 | C2: 33147 | D2: 32060 | E2: Creme Para Pentear Definicao Natural Salon Line Cachos 1kg
A3: 34794 | D3: 33095 | E3: CACHOS DOS SONHOS ÓLEO SÉRUM DEFINIÇÃO NATURAL MULTY 200ML
A4: 34665 | D4: 33107 | E4: Gelatina #Todecacho Definicao Natural 550g Salon Line
A5: 34793
A6: 34847 | C6: 32980 | D6: 95701 | E6: Creme Para Pentear Definicao Maxima 1kg - Salon Line
A7: 32137 | D7: 32060 | E7: Creme Para Pentear Definicao Natural Salon Line Cachos 1kg
A8: 95701 | D8: 32920 | E8: Creme Pentear Oleo Extraordinario Uva + Melancia Salon Line
A9: 32920
A10: 33095 | C10: 32180 | D10: 34847 | E10: Cremascara 2 Em 1 S.O.S Cachos Super Oleos 1kg Salon Line
A11: 33107 | D11: 34794 | E11: Condicionador Cachos Super Óleos | Salon Line SOS Cachos
A12: 32060 | D12: 95269 | E12: Creme para Pentear Salon Line SOS Cachos Super Óleos 300ml
D13: 34665 | E13: Ativador de Cachos Salon Line Super Óleos 500ml | S.O.S Cachos
D14: 34793 | E14: Shampoo Nutritivo SOS Cachos Super Óleos 300ml | Salon Line
D15: 32137 | E15: Oleo De Tratamento Super Oleos S.O.S Cachos 42ml Salon Line

Sheet BASE
A1: SKU | B1: Curva | C1: Situação | D1: Paletização | E1: UN/CX
A2: 32035 | B2: A | C2: ATIVO | D2: 1452 | E2: 6
A3: 33401 | B3: A | C3: ATIVO | D3: 1260 | E3: 6
A4: 33318 | B4: A | C4: ATIVO | D4: 750 | E4: 6
A5: 32248 | B5: A | C5: ATIVO | D5: 480 | E5: 6
A6: 95116 | B6: A | C6: ATIVO | D6: 1560 | E6: 12
A7: 30745 | B7: A | C7: ATIVO | D7: 480 | E7: 6
A8: 33252 | B8: A | C8: ATIVO | D8: 672 | E8: 6
A9: 32616 | B9: A | C9: ATIVO | D9: 480 | E9: 6
A10: 34682 | B10: A | C10: ATIVO | D10: 390 | E10: 6
A11: 43317 | B11: A | C11: ATIVO | D11: 1080 | E11: 12
A12: 33342 | B12: A | C12: ATIVO | D12: 462 | E12: 6
A13: 33266 | B13: A | C13: ATIVO | D13: 672 | E13: 6
... A360: 32893 | B360: C | C360: INATIVO | D360: 8352 | E360: 12
A361: 33131 | B361: C | C361: #N/A | D361: 0 | E361: 0
A362: 33268 | B362: C | C362: ATIVO | D362: 6048 | E362: 12
A363: 34171 | B363: C | C363: INATIVO | D363: 1080 | E363: 12
A364: 34172 | B364: C | C364: INATIVO | D364: 1080 | E364: 12
A365: 34175 | B365: C | C365: INATIVO | D365: 1200 | E365: 12
A366: 34305 | B366: C | C366: INATIVO | D366: 960 | E366: 6
A367: 34306 | B367: C | C367: INATIVO | D367: 960 | E367: 6
A368: 34310 | B368: C | C368: INATIVO | D368: 960 | E368: 6
A369: 34311 | B369: C | C369: INATIVO | D369: 960 | E369: 6
A370: 34484 | B370: C | C370: INATIVO | D370: 1224 | E370: 6
A371: 34489 | B371: C | C371: INATIVO | D371: 1224 | E371: 6
A372: 34566 | B372: C | C372: INATIVO | D372: 1560 | E372: 12
A373: 34698 | B373: C | C373: INATIVO | D373: 0 | E373: 0
... A524: 32789 | B524: C | C524: INATIVO | D524: 960 | E524: 6

Sheet PENDENTE
A1: AGUARDANDO SEPARAÇÃO | B1: (Tudo)
A2: TOTAL FINAL | B2: (Tudo)
A3: SHERINK ENVIADO | B3: (Tudo)
A4: SHERINK? | B4: NÃO | J4: LISTA | K4: (Tudo)
A6: OPERAÇÃO | B6: LISTA | C6: SKU | D6: TOTAL LISTA | E6: SHERINK ENVIADO | F6: AGUARDANDO SEPARAÇÃO | G6: TOTAL PENDENTE | H6: FINALIZADO | J6: OPERAÇÕES | K6: Soma de KIT | L6: TOTAL LISTA (LISTA) | M6: PENDENTE (LISTA)
A7: MERCADO LIVRE | B7: MELI_01 | C7: 30514 | D7: 996 | E7: 0 | F7: 0 | G7: 0 | H7: 996 | J7: MERCADO LIVRE | K7: 7245 | L7: 33504 | M7: -24858
A8: MERCADO LIVRE | B8: MELI_01 | C8: 30681 | D8: 2826 | E8: 0 | F8: 0 | G8: -1584 | H8: 1242 | J8: SHOPEE | K8: 0 | L8: 871248 | M8: -75987
A9: MERCADO LIVRE | B9: MELI_01 | C9: 31185 | D9: 186 | E9: 0 | F9: 0 | G9: 0 | H9: 186 | J9: Total Geral | K9: 7245 | L9: 904752 | M9: -100845
A10: MERCADO LIVRE | B10: MELI_01 | C10: 31690 | D10: 312 | E10: 0 | F10: 0 | G10: 0 | H10: 312
A11: MERCADO LIVRE | B11: MELI_01 | C11: 32022 | D11: 450 | E11: 0 | F11: 0 | G11: 0 | H11: 450
A12: MERCADO LIVRE | B12: MELI_01 | C12: 32035 | D12: 972 | E12: 0 | F12: 0 | G12: 0 | H12: 972
A13: MERCADO LIVRE | B13: MELI_01 | C13: 32137 | D13: 1272 | E13: 0 | F13: 0 | G13: 0 | H13: 1335
A14: MERCADO LIVRE | B14: MELI_01 | C14: 32259 | D14: 24 | E14: 0 | F14: 0 | G14: 0 | H14: 24
A15: MERCADO LIVRE | B15: MELI_01 | C15: 32920 | D15: 432 | E15: 0 | F15: 0 | G15: -432 | H15: 329
A16: MERCADO LIVRE | B16: MELI_01 | C16: 33095 | D16: 558 | E16: 0 | F16: 558 | G16: -1960 | H16: 0
A17: MERCADO LIVRE | B17: MELI_01 | C17: 33296 | D17: 240 | E17: 0 | F17: 240 | G17: 0 | H17: 0
A18: MERCADO LIVRE | B18: MELI_01 | C18: 33316 | D18: 102 | E18: 0 | F18: 0 | G18: 0 | H18: 102
A19: MERCADO LIVRE | B19: MELI_01 | C19: 33452 | D19: 504 | E19: 0 | F19: 0 | G19: 0 | H19: 504
A20: MERCADO LIVRE | B20: MELI_01 | C20: 34451 | D20: 1380 | E20: 0 | F20: 720 | G20: 0 | H20: 660
A21: MERCADO LIVRE | B21: MELI_01 | C21: 34665 | D21: 0 | E21: 0 | F21: 0 | G21: 0 | H21: 63
... A476: SHOPEE | B476: LIST_09 | C476: 32636 | D476: 24 | E476: 0 | F476: 24 | G476: 0 | H476: 0
A477: Total Geral | D477: 318813 | E477: 0 | F477: 97311 | G477: -15283 | H477: 208823

Sheet PLANEJAMENTO
I1: =SUBTOTAL(9,PLANEJAMENTO[AGUARDANDO SEPARAÇÃO]) -> 173277 | J1: =SUBTOTAL(9,PLANEJAMENTO[DEVOLUÇÃO MERCO]) -> 0 | L1: =SUBTOTAL(9,PLANEJAMENTO[SHERINK ENVIADO]) -> 27354 | M1: =SUBTOTAL(9,PLANEJAMENTO[FINALIZADO]) -> 765192 | N1: =SUBTOTAL(9,PLANEJAMENTO[KIT]) -> 7245 | O1: =SUBTOTAL(9,PLANEJAMENTO[TOTAL LISTA]) -> 1388046 | P1: =M1/O1 -> 0.5512728 | T1: =SUBTOTAL(9,PLANEJAMENTO[PALETE]) -> 0 | U1: =SUBTOTAL(9,PLANEJAMENTO[UNIDADE]) -> 0 | V1: =SUBTOTAL(9,PLANEJAMENTO[VOLUMES]) -> 0
A2: LISTA | B2: OPERAÇÃO | C2: SKU | D2: Descrição | E2: Curva | F2: Situação | G2: PALETIZAÇÃO | H2: CX/UN. | I2: AGUARDANDO SEPARAÇÃO | J2: DEVOLUÇÃO MERCO | K2: SHERINK SOLICITADO | L2: SHERINK ENVIADO | M2: FINALIZADO | N2: KIT | O2: TOTAL LISTA | P2: TOTAL FINAL | Q2: SALDO MERCO | R2: SALDO LMX | S2: SALDO DEVINTEX | T2: PALETE | U2: UNIDADE | V2: VOLUMES | W2: SHERINK? | X2: KIT? | Y2: ATENDIMENTO%
A3: LIST_06 | B3: SHOPEE | C3: 32060 | D3: CREME PARA PENTEAR CONDICIONADOR DEFINIÇÃO NATURAL 1KG | E3: A | F3: ATIVO | G3: 480 | H3: 6 | I3: =SUMIFS(IN_TRANSITO!E:E,IN_TRANSITO!B:B,PLANEJAMENTO!C3,IN_TRANSITO!H:H,PLANEJAMENTO!$I$2,IN_TRANSITO!W:W,PLANEJAMENTO!A3) -> 0 | J3: =SUMIFS(IN_TRANSITO!E:E,IN_TRANSITO!B:B,PLANEJAMENTO!C3,IN_TRANSITO!H:H,PLANEJAMENTO!$J$2,IN_TRANSITO!W:W,PLANEJAMENTO!A3) -> 0 | K3: =SUMIFS(PRODUCAO_SHRINK!E:E,PRODUCAO_SHRINK!B:B,PLANEJAMENTO[[#This Row],[SKU]],PRODUCAO_SHRINK!H:H,PLANEJAMENTO[[#Headers],[SHERINK SOLICITADO]],PRODUCAO_SHRINK!V:V,PLANEJAMENTO[[#This Row],[LISTA]]) -> 0 | L3: =SUMIFS(PRODUCAO_SHRINK!E:E,PRODUCAO_SHRINK!B:B,PLANEJAMENTO[[#This Row],[SKU]],PRODUCAO_SHRINK!H:H,PLANEJAMENTO[[#Headers],[SHERINK ENVIADO]],PRODUCAO_SHRINK!V:V,PLANEJAMENTO[[#This Row],[LISTA]]) -> 0 | M3: =SUMIFS(IN_TRANSITO!E:E,IN_TRANSITO!B:B,PLANEJAMENTO!C3,IN_TRANSITO!H:H,PLANEJAMENTO!$M$2,IN_TRANSITO!W:W,PLANEJAMENTO!A3) -> 17022 | N3: 0 | O3: 17022 | P3: =(PLANEJAMENTO[[#This Row],[AGUARDANDO SEPARAÇÃO]]+PLANEJAMENTO[[#This Row],[FINALIZADO]])-(PLANEJAMENTO[[#This Row],[TOTAL LISTA]]+PLANEJAMENTO[[#This Row],[KIT]]) -> 0 | Q3: =IFERROR(VLOOKUP(PLANEJAMENTO[[#This Row],[SKU]],EST_MERCOCAMP!A:E,5,0),0) -> 19698 | R3: =IFERROR(VLOOKUP(PLANEJAMENTO[[#This Row],[SKU]],EST_LMX!A:C,3,0),0) -> 11174 | S3: =IFERROR(IF(VLOOKUP(C3,'EST_DEVINTEX X DEMANDA'!A:E,5,0)<0,0,VLOOKUP(C3,'EST_DEVINTEX X DEMANDA'!A:E,5,0)),0) -> 58446 | U3: =T3*G3 -> 0 | V3: =U3/H3 -> 0 | W3: NÃO | X3: NÃO | Y3: =(PLANEJAMENTO[[#This Row],[AGUARDANDO SEPARAÇÃO]]+PLANEJAMENTO[[#This Row],[FINALIZADO]])/(PLANEJAMENTO[[#This Row],[KIT]]+PLANEJAMENTO[[#This Row],[TOTAL LISTA]]) -> 1
A4: LIST_06 | B4: SHOPEE | C4: 95505 | D4: #TODECACHINHO CREME CONDICIONADOR MULTIFUNCIONAL BABY 300ML | E4: B | F4: ATIVO | G4: 1260 | H4: 6 | I4: =SUMIFS(IN_TRANSITO!E:E,IN_TRANSITO!B:B,PLANEJAMENTO!C4,IN_TRANSITO!H:H,PLANEJAMENTO!$I$2,IN_TRANSITO!W:W,PLANEJAMENTO!A4) -> 0 | J4: =SUMIFS(IN_TRANSITO!E:E,IN_TRANSITO!B:B,PLANEJAMENTO!C4,IN_TRANSITO!H:H,PLANEJAMENTO!$J$2,IN_TRANSITO!W:W,PLANEJAMENTO!A4) -> 0 | K4: =SUMIFS(PRODUCAO_SHRINK!E:E,PRODUCAO_SHRINK!B:B,PLANEJAMENTO[[#This Row],[SKU]],PRODUCAO_SHRINK!H:H,PLANEJAMENTO[[#Headers],[SHERINK SOLICITADO]],PRODUCAO_SHRINK!V:V,PLANEJAMENTO[[#This Row],[LISTA]]) -> 0 | L4: =SUMIFS(PRODUCAO_SHRINK!E:E,PRODUCAO_SHRINK!B:B,PLANEJAMENTO[[#This Row],[SKU]],PRODUCAO_SHRINK!H:H,PLANEJAMENTO[[#Headers],[SHERINK ENVIADO]],PRODUCAO_SHRINK!V:V,PLANEJAMENTO[[#This Row],[LISTA]]) -> 0 | M4: =SUMIFS(IN_TRANSITO!E:E,IN_TRANSITO!B:B,PLANEJAMENTO!C4,IN_TRANSITO!H:H,PLANEJAMENTO!$M$2,IN_TRANSITO!W:W,PLANEJAMENTO!A4) -> 7578 | N4: 0 | O4: 7578 | P4: =(PLANEJAMENTO[[#This Row],[AGUARDANDO SEPARAÇÃO]]+PLANEJAMENTO[[#This Row],[FINALIZADO]])-(PLANEJAMENTO[[#This Row],[TOTAL LISTA]]+PLANEJAMENTO[[#This Row],[KIT]]) -> 0 | Q4: =IFERROR(VLOOKUP(PLANEJAMENTO[[#This Row],[SKU]],EST_MERCOCAMP!A:E,5,0),0) -> -1914 | R4: =IFERROR(VLOOKUP(PLANEJAMENTO[[#This Row],[SKU]],EST_LMX!A:C,3,0),0) -> 126 | S4: =IFERROR(IF(VLOOKUP(C4,'EST_DEVINTEX X DEMANDA'!A:E,5,0)<0,0,VLOOKUP(C4,'EST_DEVINTEX X DEMANDA'!A:E,5,0)),0) -> 12854 | U4: =T4*G4 -> 0 | V4: =U4/H4 -> 0 | W4: NÃO | X4: NÃO | Y4: =(PLANEJAMENTO[[#This Row],[AGUARDANDO SEPARAÇÃO]]+PLANEJAMENTO[[#This Row],[FINALIZADO]])/(PLANEJAMENTO[[#This Row],[KIT]]+PLANEJAMENTO[[#This Row],[TOTAL LISTA]]) -> 1
A5: LIST_06 | B5: SHOPEE | C5: 32259 | D5: S.O.S ÓLEO CONDICIONADOR 10 EM 1 MULTIBENEFICIOS + PODEROSOS 42ML | E5: A | F5: ATIVO | G5: 8544 | H5: 12 | I5: =SUMIFS(IN_TRANSITO!E:E,IN_TRANSITO!B:B,PLANEJAMENTO!C5,IN_TRANSITO!H:H,PLANEJAMENTO!$I$2,IN_TRANSITO!W:W,PLANEJAMENTO!A5) -> 0 | J5: =SUMIFS(IN_TRANSITO!E:E,IN_TRANSITO!B:B,PLANEJAMENTO!C5,IN_TRANSITO!H:H,PLANEJAMENTO!$J$2,IN_TRANSITO!W:W,PLANEJAMENTO!A5) -> 0 | K5: =SUMIFS(PRODUCAO_SHRINK!E:E,PRODUCAO_SHRINK!B:B,PLANEJAMENTO[[#This Row],[SKU]],PRODUCAO_SHRINK!H:H,PLANEJAMENTO[[#Headers],[SHERINK SOLICITADO]],PRODUCAO_SHRINK!V:V,PLANEJAMENTO[[#This Row],[LISTA]]) -> 0 | L5: =SUMIFS(PRODUCAO_SHRINK!E:E,PRODUCAO_SHRINK!B:B,PLANEJAMENTO[[#This Row],[SKU]],PRODUCAO_SHRINK!H:H,PLANEJAMENTO[[#Headers],[SHERINK ENVIADO]],PRODUCAO_SHRINK!V:V,PLANEJAMENTO[[#This Row],[LISTA]]) -> 0 | M5: =SUMIFS(IN_TRANSITO!E:E,IN_TRANSITO!B:B,PLANEJAMENTO!C5,IN_TRANSITO!H:H,PLANEJAMENTO!$M$2,IN_TRANSITO!W:W,PLANEJAMENTO!A5) -> 4488 | N5: 0 | O5: 4488 | P5: =(PLANEJAMENTO[[#This Row],[AGUARDANDO SEPARAÇÃO]]+PLANEJAMENTO[[#This Row],[FINALIZADO]])-(PLANEJAMENTO[[#This Row],[TOTAL LISTA]]+PLANEJAMENTO[[#This Row],[KIT]]) -> 0 | Q5: =IFERROR(VLOOKUP(PLANEJAMENTO[[#This Row],[SKU]],EST_MERCOCAMP!A:E,5,0),0) -> 21780 | R5: =IFERROR(VLOOKUP(PLANEJAMENTO[[#This Row],[SKU]],EST_LMX!A:C,3,0),0) -> 978 | S5: =IFERROR(IF(VLOOKUP(C5,'EST_DEVINTEX X DEMANDA'!A:E,5,0)<0,0,VLOOKUP(C5,'EST_DEVINTEX X DEMANDA'!A:E,5,0)),0) -> 24348 | U5: =T5*G5 -> 0 | V5: =U5/H5 -> 0 | W5: SIM | X5: NÃO | Y5: =(PLANEJAMENTO[[#This Row],[AGUARDANDO SEPARAÇÃO]]+PLANEJAMENTO[[#This Row],[FINALIZADO]])/(PLANEJAMENTO[[#This Row],[KIT]]+PLANEJAMENTO[[#This Row],[TOTAL LISTA]]) -> 1
A6: LIST_06 | B6: SHOPEE | C6: 32137 | D6: OLEO SOS CACHOS SUPER OLEOS CONDICIONADOR 42ML | E6: A | F6: ATIVO | G6: 8544 | H6: 12 | I6: =SUMIFS(IN_TRANSITO!E:E,IN_TRANSITO!B:B,PLANEJAMENTO!C6,IN_TRANSITO!H:H,PLANEJAMENTO!$I$2,IN_TRANSITO!W:W,PLANEJAMENTO!A6) -> 0 | J6: =SUMIFS(IN_TRANSITO!E:E,IN_TRANSITO!B:B,PLANEJAMENTO!C6,IN_TRANSITO!H:H,PLANEJAMENTO!$J$2,IN_TRANSITO!W:W,PLANEJAMENTO!A6) -> 0 | K6: =SUMIFS(PRODUCAO_SHRINK!E:E,PRODUCAO_SHRINK!B:B,PLANEJAMENTO[[#This Row],[SKU]],PRODUCAO_SHRINK!H:H,PLANEJAMENTO[[#Headers],[SHERINK SOLICITADO]],PRODUCAO_SHRINK!V:V,PLANEJAMENTO[[#This Row],[LISTA]]) -> 0 | L6: =SUMIFS(PRODUCAO_SHRINK!E:E,PRODUCAO_SHRINK!B:B,PLANEJAMENTO[[#This Row],[SKU]],PRODUCAO_SHRINK!H:H,PLANEJAMENTO[[#Headers],[SHERINK ENVIADO]],PRODUCAO_SHRINK!V:V,PLANEJAMENTO[[#This Row],[LISTA]]) -> 0 | M6: =SUMIFS(IN_TRANSITO!E:E,IN_TRANSITO!B:B,PLANEJAMENTO!C6,IN_TRANSITO!H:H,PLANEJAMENTO!$M$2,IN_TRANSITO!W:W,PLANEJAMENTO!A6) -> 8712 | N6: 0 | O6: 8712 | P6: =(PLANEJAMENTO[[#This Row],[AGUARDANDO SEPARAÇÃO]]+PLANEJAMENTO[[#This Row],[FINALIZADO]])-(PLANEJAMENTO[[#This Row],[TOTAL LISTA]]+PLANEJAMENTO[[#This Row],[KIT]]) -> 0 | Q6: =IFERROR(VLOOKUP(PLANEJAMENTO[[#This Row],[SKU]],EST_MERCOCAMP!A:E,5,0),0) -> 11244 | R6: =IFERROR(VLOOKUP(PLANEJAMENTO[[#This Row],[SKU]],EST_LMX!A:C,3,0),0) -> 11646 | S6: =IFERROR(IF(VLOOKUP(C6,'EST_DEVINTEX X DEMANDA'!A:E,5,0)<0,0,VLOOKUP(C6,'EST_DEVINTEX X DEMANDA'!A:E,5,0)),0) -> 29904 | U6: =T6*G6 -> 0 | V6: =U6/H6 -> 0 | W6: SIM | X6: NÃO | Y6: =(PLANEJAMENTO[[#This Row],[AGUARDANDO SEPARAÇÃO]]+PLANEJAMENTO[[#This Row],[FINALIZADO]])/(PLANEJAMENTO[[#This Row],[KIT]]+PLANEJAMENTO[[#This Row],[TOTAL LISTA]]) -> 1
A7: LIST_06 | B7: SHOPEE | C7: 33271 | D7: CREME PARA PENTEAR CACHOS OSTENTAÇÃO 1KG | E7: A | F7: ATIVO | G7: 480 | H7: 6 | I7: =SUMIFS(IN_TRANSITO!E:E,IN_TRANSITO!B:B,PLANEJAMENTO!C7,IN_TRANSITO!H:H,PLANEJAMENTO!$I$2,IN_TRANSITO!W:W,PLANEJAMENTO!A7) -> 0 | J7: =SUMIFS(IN_TRANSITO!E:E,IN_TRANSITO!B:B,PLANEJAMENTO!C7,IN_TRANSITO!H:H,PLANEJAMENTO!$J$2,IN_TRANSITO!W:W,PLANEJAMENTO!A7) -> 0 | K7: =SUMIFS(PRODUCAO_SHRINK!E:E,PRODUCAO_SHRINK!B:B,PLANEJAMENTO[[#This Row],[SKU]],PRODUCAO_SHRINK!H:H,PLANEJAMENTO[[#Headers],[SHERINK SOLICITADO]],PRODUCAO_SHRINK!V:V,PLANEJAMENTO[[#This Row],[LISTA]]) -> 0 | L7: =SUMIFS(PRODUCAO_SHRINK!E:E,PRODUCAO_SHRINK!B:B,PLANEJAMENTO[[#This Row],[SKU]],PRODUCAO_SHRINK!H:H,PLANEJAMENTO[[#Headers],[SHERINK ENVIADO]],PRODUCAO_SHRINK!V:V,PLANEJAMENTO[[#This Row],[LISTA]]) -> 0 | M7: =SUMIFS(IN_TRANSITO!E:E,IN_TRANSITO!B:B,PLANEJAMENTO!C7,IN_TRANSITO!H:H,PLANEJAMENTO!$M$2,IN_TRANSITO!W:W,PLANEJAMENTO!A7) -> 5196 | N7: 0 | O7: 5196 | P7: =(PLANEJAMENTO[[#This Row],[AGUARDANDO SEPARAÇÃO]]+PLANEJAMENTO[[#This Row],[FINALIZADO]])-(PLANEJAMENTO[[#This Row],[TOTAL LISTA]]+PLANEJAMENTO[[#This Row],[KIT]]) -> 0 | Q7: =IFERROR(VLOOKUP(PLANEJAMENTO[[#This Row],[SKU]],EST_MERCOCAMP!A:E,5,0),0) -> 16488 | R7: =IFERROR(VLOOKUP(PLANEJAMENTO[[#This Row],[SKU]],EST_LMX!A:C,3,0),0) -> 8148 | S7: =IFERROR(IF(VLOOKUP(C7,'EST_DEVINTEX X DEMANDA'!A:E,5,0)<0,0,VLOOKUP(C7,'EST_DEVINTEX X DEMANDA'!A:E,5,0)),0) -> 8244 | U7: =T7*G7 -> 0 | V7: =U7/H7 -> 0 | W7: NÃO | X7: NÃO | Y7: =(PLANEJAMENTO[[#This Row],[AGUARDANDO SEPARAÇÃO]]+PLANEJAMENTO[[#This Row],[FINALIZADO]])/(PLANEJAMENTO[[#This Row],[KIT]]+PLANEJAMENTO[[#This Row],[TOTAL LISTA]]) -> 1
A8: LIST_06 | B8: SHOPEE | C8: 95127 | D8: BOMBA TONICO CONDICIONANTE FORT CRESCIMENTO 100ML | E8: B | F8: ATIVO | G8: 3384 | H8: 12 | I8: =SUMIFS(IN_TRANSITO!E:E,IN_TRANSITO!B:B,PLANEJAMENTO!C8,IN_TRANSITO!H:H,PLANEJAMENTO!$I$2,IN_TRANSITO!W:W,PLANEJAMENTO!A8) -> 0 | J8: =SUMIFS(IN_TRANSITO!E:E,IN_TRANSITO!B:B,PLANEJAMENTO!C8,IN_TRANSITO!H:H,PLANEJAMENTO!$J$2,IN_TRANSITO!W:W,PLANEJAMENTO!A8) -> 0 | K8: =SUMIFS(PRODUCAO_SHRINK!E:E,PRODUCAO_SHRINK!B:B,PLANEJAMENTO[[#This Row],[SKU]],PRODUCAO_SHRINK!H:H,PLANEJAMENTO[[#Headers],[SHERINK SOLICITADO]],PRODUCAO_SHRINK!V:V,PLANEJAMENTO[[#This Row],[LISTA]]) -> 0 | L8: =SUMIFS(PRODUCAO_SHRINK!E:E,PRODUCAO_SHRINK!B:B,PLANEJAMENTO[[#This Row],[SKU]],PRODUCAO_SHRINK!H:H,PLANEJAMENTO[[#Headers],[SHERINK ENVIADO]],PRODUCAO_SHRINK!V:V,PLANEJAMENTO[[#This Row],[LISTA]]) -> 0 | M8: =SUMIFS(IN_TRANSITO!E:E,IN_TRANSITO!B:B,PLANEJAMENTO!C8,IN_TRANSITO!H:H,PLANEJAMENTO!$M$2,IN_TRANSITO!W:W,PLANEJAMENTO!A8) -> 4392 | N8: 0 | O8: 4392 | P8: =(PLANEJAMENTO[[#This Row],[AGUARDANDO SEPARAÇÃO]]+PLANEJAMENTO[[#This Row],[FINALIZADO]])-(PLANEJAMENTO[[#This Row],[TOTAL LISTA]]+PLANEJAMENTO[[#This Row],[KIT]]) -> 0 | Q8: =IFERROR(VLOOKUP(PLANEJAMENTO[[#This Row],[SKU]],EST_MERCOCAMP!A:E,5,0),0) -> 4176 | R8: =IFERROR(VLOOKUP(PLANEJAMENTO[[#This Row],[SKU]],EST_LMX!A:C,3,0),0) -> 6024 | S8: =IFERROR(IF(VLOOKUP(C8,'EST_DEVINTEX X DEMANDA'!A:E,5,0)<0,0,VLOOKUP(C8,'EST_DEVINTEX X DEMANDA'!A:E,5,0)),0) -> 12420 | U8: =T8*G8 -> 0 | V8: =U8/H8 -> 0 | W8: NÃO | X8: NÃO | Y8: =(PLANEJAMENTO[[#This Row],[AGUARDANDO SEPARAÇÃO]]+PLANEJAMENTO[[#This Row],[FINALIZADO]])/(PLANEJAMENTO[[#This Row],[KIT]]+PLANEJAMENTO[[#This Row],[TOTAL LISTA]]) -> 1
A9: LIST_06 | B9: SHOPEE | C9: 95679 | D9: #TODECACHO GELATINA CONDICIONANTE SUPER DEFINICAO 1KG | E9: A | F9: ATIVO | G9: 480 | H9: 6 | I9: =SUMIFS(IN_TRANSITO!E:E,IN_TRANSITO!B:B,PLANEJAMENTO!C9,IN_TRANSITO!H:H,PLANEJAMENTO!$I$2,IN_TRANSITO!W:W,PLANEJAMENTO!A9) -> 0 | J9: =SUMIFS(IN_TRANSITO!E:E,IN_TRANSITO!B:B,PLANEJAMENTO!C9,IN_TRANSITO!H:H,PLANEJAMENTO!$J$2,IN_TRANSITO!W:W,PLANEJAMENTO!A9) -> 0 | K9: =SUMIFS(PRODUCAO_SHRINK!E:E,PRODUCAO_SHRINK!B:B,PLANEJAMENTO[[#This Row],[SKU]],PRODUCAO_SHRINK!H:H,PLANEJAMENTO[[#Headers],[SHERINK SOLICITADO]],PRODUCAO_SHRINK!V:V,PLANEJAMENTO[[#This Row],[LISTA]]) -> 0 | L9: =SUMIFS(PRODUCAO_SHRINK!E:E,PRODUCAO_SHRINK!B:B,PLANEJAMENTO[[#This Row],[SKU]],PRODUCAO_SHRINK!H:H,PLANEJAMENTO[[#Headers],[SHERINK ENVIADO]],PRODUCAO_SHRINK!V:V,PLANEJAMENTO[[#This Row],[LISTA]]) -> 0 | M9: =SUMIFS(IN_TRANSITO!E:E,IN_TRANSITO!B:B,PLANEJAMENTO!C9,IN_TRANSITO!H:H,PLANEJAMENTO!$M$2,IN_TRANSITO!W:W,PLANEJAMENTO!A9) -> 4902 | N9: 0 | O9: 4902 | P9: =(PLANEJAMENTO[[#This Row],[AGUARDANDO SEPARAÇÃO]]+PLANEJAMENTO[[#This Row],[FINALIZADO]])-(PLANEJAMENTO[[#This Row],[TOTAL LISTA]]+PLANEJAMENTO[[#This Row],[KIT]]) -> 0 | Q9: =IFERROR(VLOOKUP(PLANEJAMENTO[[#This Row],[SKU]],EST_MERCOCAMP!A:E,5,0),0) -> -4668 | R9: =IFERROR(VLOOKUP(PLANEJAMENTO[[#This Row],[SKU]],EST_LMX!A:C,3,0),0) -> 4830 | S9: =IFERROR(IF(VLOOKUP(C9,'EST_DEVINTEX X DEMANDA'!A:E,5,0)<0,0,VLOOKUP(C9,'EST_DEVINTEX X DEMANDA'!A:E,5,0)),0) -> 17034 | U9: =T9*G9 -> 0 | V9: =U9/H9 -> 0 | W9: NÃO | X9: NÃO | Y9: =(PLANEJAMENTO[[#This Row],[AGUARDANDO SEPARAÇÃO]]+PLANEJAMENTO[[#This Row],[FINALIZADO]])/(PLANEJAMENTO[[#This Row],[KIT]]+PLANEJAMENTO[[#This Row],[TOTAL LISTA]]) -> 1
A10: LIST_06 | B10: SHOPEE | C10: 34988 | D10: SOS HIDRATACAO MASCARA CONDICIONANTE OLEO DE RICINO 1KG | E10: B | F10: ATIVO | G10: 480 | H10: 6 | I10: =SUMIFS(IN_TRANSITO!E:E,IN_TRANSITO!B:B,PLANEJAMENTO!C10,IN_TRANSITO!H:H,PLANEJAMENTO!$I$2,IN_TRANSITO!W:W,PLANEJAMENTO!A10) -> 0 | J10: =SUMIFS(IN_TRANSITO!E:E,IN_TRANSITO!B:B,PLANEJAMENTO!C10,IN_TRANSITO!H:H,PLANEJAMENTO!$J$2,IN_TRANSITO!W:W,PLANEJAMENTO!A10) -> 0 | K10: =SUMIFS(PRODUCAO_SHRINK!E:E,PRODUCAO_SHRINK!B:B,PLANEJAMENTO[[#This Row],[SKU]],PRODUCAO_SHRINK!H:H,PLANEJAMENTO[[#Headers],[SHERINK SOLICITADO]],PRODUCAO_SHRINK!V:V,PLANEJAMENTO[[#This Row],[LISTA]]) -> 0 | L10: =SUMIFS(PRODUCAO_SHRINK!E:E,PRODUCAO_SHRINK!B:B,PLANEJAMENTO[[#This Row],[SKU]],PRODUCAO_SHRINK!H:H,PLANEJAMENTO[[#Headers],[SHERINK ENVIADO]],PRODUCAO_SHRINK!V:V,PLANEJAMENTO[[#This Row],[LISTA]]) -> 0 | M10: =SUMIFS(IN_TRANSITO!E:E,IN_TRANSITO!B:B,PLANEJAMENTO!C10,IN_TRANSITO!H:H,PLANEJAMENTO!$M$2,IN_TRANSITO!W:W,PLANEJAMENTO!A10) -> 8340 | N10: 0 | O10: 8340 | P10: =(PLANEJAMENTO[[#This Row],[AGUARDANDO SEPARAÇÃO]]+PLANEJAMENTO[[#This Row],[FINALIZADO]])-(PLANEJAMENTO[[#This Row],[TOTAL LISTA]]+PLANEJAMENTO[[#This Row],[KIT]]) -> 0 | Q10: =IFERROR(VLOOKUP(PLANEJAMENTO[[#This Row],[SKU]],EST_MERCOCAMP!A:E,5,0),0) -> -1812 | R10: =IFERROR(VLOOKUP(PLANEJAMENTO[[#This Row],[SKU]],EST_LMX!A:C,3,0),0) -> 5400 | S10: =IFERROR(IF(VLOOKUP(C10,'EST_DEVINTEX X DEMANDA'!A:E,5,0)<0,0,VLOOKUP(C10,'EST_DEVINTEX X DEMANDA'!A:E,5,0)),0) -> 2700 | U10: =T10*G10 -> 0 | V10: =U10/H10 -> 0 | W10: NÃO | X10: NÃO | Y10: =(PLANEJAMENTO[[#This Row],[AGUARDANDO SEPARAÇÃO]]+PLANEJAMENTO[[#This Row],[FINALIZADO]])/(PLANEJAMENTO[[#This Row],[KIT]]+PLANEJAMENTO[[#This Row],[TOTAL LISTA]]) -> 1
A11: LIST_06 | B11: SHOPEE | C11: 32022 | D11: MEU LISO CONDICIONADOR DEMAIS SPRAY DEFRIZANTE PROTETOR TÉRMICO 240ML | E11: B | F11: ATIVO | G11: 1584 | H11: 6 | I11: =SUMIFS(IN_TRANSITO!E:E,IN_TRANSITO!B:B,PLANEJAMENTO!C11,IN_TRANSITO!H:H,PLANEJAMENTO!$I$2,IN_TRANSITO!W:W,PLANEJAMENTO!A11) -> 0 | J11: =SUMIFS(IN_TRANSITO!E:E,IN_TRANSITO!B:B,PLANEJAMENTO!C11,IN_TRANSITO!H:H,PLANEJAMENTO!$J$2,IN_TRANSITO!W:W,PLANEJAMENTO!A11) -> 0 | K11: =SUMIFS(PRODUCAO_SHRINK!E:E,PRODUCAO_SHRINK!B:B,PLANEJAMENTO[[#This Row],[SKU]],PRODUCAO_SHRINK!H:H,PLANEJAMENTO[[#Headers],[SHERINK SOLICITADO]],PRODUCAO_SHRINK!V:V,PLANEJAMENTO[[#This Row],[LISTA]]) -> 0 | L11: =SUMIFS(PRODUCAO_SHRINK!E:E,PRODUCAO_SHRINK!B:B,PLANEJAMENTO[[#This Row],[SKU]],PRODUCAO_SHRINK!H:H,PLANEJAMENTO[[#Headers],[SHERINK ENVIADO]],PRODUCAO_SHRINK!V:V,PLANEJAMENTO[[#This Row],[LISTA]]) -> 0 | M11: =SUMIFS(IN_TRANSITO!E:E,IN_TRANSITO!B:B,PLANEJAMENTO!C11,IN_TRANSITO!H:H,PLANEJAMENTO!$M$2,IN_TRANSITO!W:W,PLANEJAMENTO!A11) -> 5874 | N11: 0 | O11: 5874 | P11: =(PLANEJAMENTO[[#This Row],[AGUARDANDO SEPARAÇÃO]]+PLANEJAMENTO[[#This Row],[FINALIZADO]])-(PLANEJAMENTO[[#This Row],[TOTAL LISTA]]+PLANEJAMENTO[[#This Row],[KIT]]) -> 0 | Q11: =IFERROR(VLOOKUP(PLANEJAMENTO[[#This Row],[SKU]],EST_MERCOCAMP!A:E,5,0),0) -> -384 | R11: =IFERROR(VLOOKUP(PLANEJAMENTO[[#This Row],[SKU]],EST_LMX!A:C,3,0),0) -> 1608 | S11: =IFERROR(IF(VLOOKUP(C11,'EST_DEVINTEX X DEMANDA'!A:E,5,0)<0,0,VLOOKUP(C11,'EST_DEVINTEX X DEMANDA'!A:E,5,0)),0) -> 16182 | U11: =T11*G11 -> 0 | V11: =U11/H11 -> 0 | W11: NÃO | X11: NÃO | Y11: =(PLANEJAMENTO[[#This Row],[AGUARDANDO SEPARAÇÃO]]+PLANEJAMENTO[[#This Row],[FINALIZADO]])/(PLANEJAMENTO[[#This Row],[KIT]]+PLANEJAMENTO[[#This Row],[TOTAL LISTA]]) -> 1
A12: LIST_06 | B12: SHOPEE | C12: 32136 | D12: OLEO SOS CACHOS OLEO DE COCO CONDICIONADOR 42ML | E12: B | F12: ATIVO | G12: 8544 | H12: 12 | I12: =SUMIFS(IN_TRANSITO!E:E,IN_TRANSITO!B:B,PLANEJAMENTO!C12,IN_TRANSITO!H:H,PLANEJAMENTO!$I$2,IN_TRANSITO!W:W,PLANEJAMENTO!A12) -> 0 | J12: =SUMIFS(IN_TRANSITO!E:E,IN_TRANSITO!B:B,PLANEJAMENTO!C12,IN_TRANSITO!H:H,PLANEJAMENTO!$J$2,IN_TRANSITO!W:W,PLANEJAMENTO!A12) -> 0 | K12: =SUMIFS(PRODUCAO_SHRINK!E:E,PRODUCAO_SHRINK!B:B,PLANEJAMENTO[[#This Row],[SKU]],PRODUCAO_SHRINK!H:H,PLANEJAMENTO[[#Headers],[SHERINK SOLICITADO]],PRODUCAO_SHRINK!V:V,PLANEJAMENTO[[#This Row],[LISTA]]) -> 0 | L12: =SUMIFS(PRODUCAO_SHRINK!E:E,PRODUCAO_SHRINK!B:B,PLANEJAMENTO[[#This Row],[SKU]],PRODUCAO_SHRINK!H:H,PLANEJAMENTO[[#Headers],[SHERINK ENVIADO]],PRODUCAO_SHRINK!V:V,PLANEJAMENTO[[#This Row],[LISTA]]) -> 0 | M12: =SUMIFS(IN_TRANSITO!E:E,IN_TRANSITO!B:B,PLANEJAMENTO!C12,IN_TRANSITO!H:H,PLANEJAMENTO!$M$2,IN_TRANSITO!W:W,PLANEJAMENTO!A12) -> 7596 | N12: 0 | O12: 7596 | P12: =(PLANEJAMENTO[[#This Row],[AGUARDANDO SEPARAÇÃO]]+PLANEJAMENTO[[#This Row],[FINALIZADO]])-(PLANEJAMENTO[[#This Row],[TOTAL LISTA]]+PLANEJAMENTO[[#This Row],[KIT]]) -> 0 | Q12: =IFERROR(VLOOKUP(PLANEJAMENTO[[#This Row],[SKU]],EST_MERCOCAMP!A:E,5,0),0) -> 28332 | R12: =IFERROR(VLOOKUP(PLANEJAMENTO[[#This Row],[SKU]],EST_LMX!A:C,3,0),0) -> 11232 | S12: =IFERROR(IF(VLOOKUP(C12,'EST_DEVINTEX X DEMANDA'!A:E,5,0)<0,0,VLOOKUP(C12,'EST_DEVINTEX X DEMANDA'!A:E,5,0)),0) -> 15060 | U12: =T12*G12 -> 0 | V12: =U12/H12 -> 0 | W12: SIM | X12: NÃO | Y12: =(PLANEJAMENTO[[#This Row],[AGUARDANDO SEPARAÇÃO]]+PLANEJAMENTO[[#This Row],[FINALIZADO]])/(PLANEJAMENTO[[#This Row],[KIT]]+PLANEJAMENTO[[#This Row],[TOTAL LISTA]]) -> 1
A13: LIST_06 | B13: SHOPEE | C13: 33095 | D13: CACHOS DOS SONHOS ÓLEO CONDICIONANTE SÉRUM DEFINIÇÃO NATURAL MULTY 200ML | E13: A | F13: ATIVO | G13: 2484 | H13: 6 | I13: =SUMIFS(IN_TRANSITO!E:E,IN_TRANSITO!B:B,PLANEJAMENTO!C13,IN_TRANSITO!H:H,PLANEJAMENTO!$I$2,IN_TRANSITO!W:W,PLANEJAMENTO!A13) -> 0 | J13: =SUMIFS(IN_TRANSITO!E:E,IN_TRANSITO!B:B,PLANEJAMENTO!C13,IN_TRANSITO!H:H,PLANEJAMENTO!$J$2,IN_TRANSITO!W:W,PLANEJAMENTO!A13) -> 0 | K13: =SUMIFS(PRODUCAO_SHRINK!E:E,PRODUCAO_SHRINK!B:B,PLANEJAMENTO[[#This Row],[SKU]],PRODUCAO_SHRINK!H:H,PLANEJAMENTO[[#Headers],[SHERINK SOLICITADO]],PRODUCAO_SHRINK!V:V,PLANEJAMENTO[[#This Row],[LISTA]]) -> 0 | L13: =SUMIFS(PRODUCAO_SHRINK!E:E,PRODUCAO_SHRINK!B:B,PLANEJAMENTO[[#This Row],[SKU]],PRODUCAO_SHRINK!H:H,PLANEJAMENTO[[#Headers],[SHERINK ENVIADO]],PRODUCAO_SHRINK!V:V,PLANEJAMENTO[[#This Row],[LISTA]]) -> 0 | M13: =SUMIFS(IN_TRANSITO!E:E,IN_TRANSITO!B:B,PLANEJAMENTO!C13,IN_TRANSITO!H:H,PLANEJAMENTO!$M$2,IN_TRANSITO!W:W,PLANEJAMENTO!A13) -> 3852 | N13: 0 | O13: 3852 | P13: =(PLANEJAMENTO[[#This Row],[AGUARDANDO SEPARAÇÃO]]+PLANEJAMENTO[[#This Row],[FINALIZADO]])-(PLANEJAMENTO[[#This Row],[TOTAL LISTA]]+PLANEJAMENTO[[#This Row],[KIT]]) -> 0 | Q13: =IFERROR(VLOOKUP(PLANEJAMENTO[[#This Row],[SKU]],EST_MERCOCAMP!A:E,5,0),0) -> -4974 | R13: =IFERROR(VLOOKUP(PLANEJAMENTO[[#This Row],[SKU]],EST_LMX!A:C,3,0),0) -> 0 | S13: =IFERROR(IF(VLOOKUP(C13,'EST_DEVINTEX X DEMANDA'!A:E,5,0)<0,0,VLOOKUP(C13,'EST_DEVINTEX X DEMANDA'!A:E,5,0)),0) -> 11298 | U13: =T13*G13 -> 0 | V13: =U13/H13 -> 0 | W13: NÃO | X13: NÃO | Y13: =(PLANEJAMENTO[[#This Row],[AGUARDANDO SEPARAÇÃO]]+PLANEJAMENTO[[#This Row],[FINALIZADO]])/(PLANEJAMENTO[[#This Row],[KIT]]+PLANEJAMENTO[[#This Row],[TOTAL LISTA]]) -> 1
A14: LIST_06 | B14: SHOPEE | C14: 33107 | D14: #TODECACHO GELATINA DEFINIÇÃO NATURAL 550G | E14: A | F14: ATIVO | G14: 960 | H14: 6 | I14: =SUMIFS(IN_TRANSITO!E:E,IN_TRANSITO!B:B,PLANEJAMENTO!C14,IN_TRANSITO!H:H,PLANEJAMENTO!$I$2,IN_TRANSITO!W:W,PLANEJAMENTO!A14) -> 0 | J14: =SUMIFS(IN_TRANSITO!E:E,IN_TRANSITO!B:B,PLANEJAMENTO!C14,IN_TRANSITO!H:H,PLANEJAMENTO!$J$2,IN_TRANSITO!W:W,PLANEJAMENTO!A14) -> 0 | K14: =SUMIFS(PRODUCAO_SHRINK!E:E,PRODUCAO_SHRINK!B:B,PLANEJAMENTO[[#This Row],[SKU]],PRODUCAO_SHRINK!H:H,PLANEJAMENTO[[#Headers],[SHERINK SOLICITADO]],PRODUCAO_SHRINK!V:V,PLANEJAMENTO[[#This Row],[LISTA]]) -> 0 | L14: =SUMIFS(PRODUCAO_SHRINK!E:E,PRODUCAO_SHRINK!B:B,PLANEJAMENTO[[#This Row],[SKU]],PRODUCAO_SHRINK!H:H,PLANEJAMENTO[[#Headers],[SHERINK ENVIADO]],PRODUCAO_SHRINK!V:V,PLANEJAMENTO[[#This Row],[LISTA]]) -> 0 | M14: =SUMIFS(IN_TRANSITO!E:E,IN_TRANSITO!B:B,PLANEJAMENTO!C14,IN_TRANSITO!H:H,PLANEJAMENTO!$M$2,IN_TRANSITO!W:W,PLANEJAMENTO!A14) -> 6600 | N14: 0 | O14: 6600 | P14: =(PLANEJAMENTO[[#This Row],[AGUARDANDO SEPARAÇÃO]]+PLANEJAMENTO[[#This Row],[FINALIZADO]])-(PLANEJAMENTO[[#This Row],[TOTAL LISTA]]+PLANEJAMENTO[[#This Row],[KIT]]) -> 0 | Q14: =IFERROR(VLOOKUP(PLANEJAMENTO[[#This Row],[SKU]],EST_MERCOCAMP!A:E,5,0),0) -> 20178 | R14: =IFERROR(VLOOKUP(PLANEJAMENTO[[#This Row],[SKU]],EST_LMX!A:C,3,0),0) -> 9174 | S14: =IFERROR(IF(VLOOKUP(C14,'EST_DEVINTEX X DEMANDA'!A:E,5,0)<0,0,VLOOKUP(C14,'EST_DEVINTEX X DEMANDA'!A:E,5,0)),0) -> 19320 | U14: =T14*G14 -> 0 | V14: =U14/H14 -> 0 | W14: NÃO | X14: NÃO | Y14: =(PLANEJAMENTO[[#This Row],[AGUARDANDO SEPARAÇÃO]]+PLANEJAMENTO[[#This Row],[FINALIZADO]])/(PLANEJAMENTO[[#This Row],[KIT]]+PLANEJAMENTO[[#This Row],[TOTAL LISTA]]) -> 1
... A803: LIST_09 | B803: SHOPEE | C803: 32636 | D803: HIDRA MARACUJA KIT SHAMPOO + CONDICIONADOR 300ML | E803: B | F803: ATIVO | G803: 720 | H803: 6 | I803: =SUMIFS(IN_TRANSITO!E:E,IN_TRANSITO!B:B,PLANEJAMENTO!C803,IN_TRANSITO!H:H,PLANEJAMENTO!$I$2,IN_TRANSITO!W:W,PLANEJAMENTO!A803) -> 0 | J803: =SUMIFS(IN_TRANSITO!E:E,IN_TRANSITO!B:B,PLANEJAMENTO!C803,IN_TRANSITO!H:H,PLANEJAMENTO!$J$2,IN_TRANSITO!W:W,PLANEJAMENTO!A803) -> 0 | K803: =SUMIFS(PRODUCAO_SHRINK!E:E,PRODUCAO_SHRINK!B:B,PLANEJAMENTO[[#This Row],[SKU]],PRODUCAO_SHRINK!H:H,PLANEJAMENTO[[#Headers],[SHERINK SOLICITADO]],PRODUCAO_SHRINK!V:V,PLANEJAMENTO[[#This Row],[LISTA]]) -> 0 | L803: =SUMIFS(PRODUCAO_SHRINK!E:E,PRODUCAO_SHRINK!B:B,PLANEJAMENTO[[#This Row],[SKU]],PRODUCAO_SHRINK!H:H,PLANEJAMENTO[[#Headers],[SHERINK ENVIADO]],PRODUCAO_SHRINK!V:V,PLANEJAMENTO[[#This Row],[LISTA]]) -> 0 | M803: =SUMIFS(IN_TRANSITO!E:E,IN_TRANSITO!B:B,PLANEJAMENTO!C803,IN_TRANSITO!H:H,PLANEJAMENTO!$M$2,IN_TRANSITO!W:W,PLANEJAMENTO!A803) -> 0 | N803: 0 | O803: 24 | P803: =(PLANEJAMENTO[[#This Row],[AGUARDANDO SEPARAÇÃO]]+PLANEJAMENTO[[#This Row],[FINALIZADO]])-(PLANEJAMENTO[[#This Row],[TOTAL LISTA]]+PLANEJAMENTO[[#This Row],[KIT]]) -> -24 | Q803: =IFERROR(VLOOKUP(PLANEJAMENTO[[#This Row],[SKU]],EST_MERCOCAMP!A:E,5,0),0) -> -42 | R803: =IFERROR(VLOOKUP(PLANEJAMENTO[[#This Row],[SKU]],EST_LMX!A:C,3,0),0) -> 1512 | S803: =IFERROR(IF(VLOOKUP(C803,'EST_DEVINTEX X DEMANDA'!A:E,5,0)<0,0,VLOOKUP(C803,'EST_DEVINTEX X DEMANDA'!A:E,5,0)),0) -> 7596 | U803: =T803*G803 -> 0 | V803: =U803/H803 -> 0 | W803: NÃO | X803: NÃO | Y803: =(PLANEJAMENTO[[#This Row],[AGUARDANDO SEPARAÇÃO]]+PLANEJAMENTO[[#This Row],[FINALIZADO]])/(PLANEJAMENTO[[#This Row],[KIT]]+PLANEJAMENTO[[#This Row],[TOTAL LISTA]]) -> 0
A804: MELI_01 | B804: MERCADO LIVRE | C804: 95269 | D804: Creme para Pentear Salon Line SOS Cachos Super Óleos 300ml | E804: =VLOOKUP(PLANEJAMENTO[[#This Row],[SKU]],BASE!A:B,2,0) -> A | F804: ATIVO | G804: =VLOOKUP(PLANEJAMENTO[[#This Row],[SKU]],BASE!A:D,4,0) -> 1620 | H804: =VLOOKUP(PLANEJAMENTO[[#This Row],[SKU]],BASE!A:E,5,0) -> 6 | I804: =SUMIFS(IN_TRANSITO!E:E,IN_TRANSITO!B:B,PLANEJAMENTO!C804,IN_TRANSITO!H:H,PLANEJAMENTO!$I$2,IN_TRANSITO!W:W,PLANEJAMENTO!A804) -> 0 | J804: =SUMIFS(IN_TRANSITO!E:E,IN_TRANSITO!B:B,PLANEJAMENTO!C804,IN_TRANSITO!H:H,PLANEJAMENTO!$J$2,IN_TRANSITO!W:W,PLANEJAMENTO!A804) -> 0 | K804: =SUMIFS(PRODUCAO_SHRINK!E:E,PRODUCAO_SHRINK!B:B,PLANEJAMENTO[[#This Row],[SKU]],PRODUCAO_SHRINK!H:H,PLANEJAMENTO[[#Headers],[SHERINK SOLICITADO]],PRODUCAO_SHRINK!V:V,PLANEJAMENTO[[#This Row],[LISTA]]) -> 0 | L804: =SUMIFS(PRODUCAO_SHRINK!E:E,PRODUCAO_SHRINK!B:B,PLANEJAMENTO[[#This Row],[SKU]],PRODUCAO_SHRINK!H:H,PLANEJAMENTO[[#Headers],[SHERINK ENVIADO]],PRODUCAO_SHRINK!V:V,PLANEJAMENTO[[#This Row],[LISTA]]) -> 0 | M804: =SUMIFS(IN_TRANSITO!E:E,IN_TRANSITO!B:B,PLANEJAMENTO!C804,IN_TRANSITO!H:H,PLANEJAMENTO!$M$2,IN_TRANSITO!W:W,PLANEJAMENTO!A804) -> 63 | N804: 63 | O804: 0 | P804: =(PLANEJAMENTO[[#This Row],[AGUARDANDO SEPARAÇÃO]]+PLANEJAMENTO[[#This Row],[FINALIZADO]])-(PLANEJAMENTO[[#This Row],[TOTAL LISTA]]+PLANEJAMENTO[[#This Row],[KIT]]) -> 0 | Q804: =IFERROR(VLOOKUP(PLANEJAMENTO[[#This Row],[SKU]],EST_MERCOCAMP!A:E,5,0),0) -> 1428 | R804: =IFERROR(VLOOKUP(PLANEJAMENTO[[#This Row],[SKU]],EST_LMX!A:C,3,0),0) -> 2076 | S804: =IFERROR(IF(VLOOKUP(C804,'EST_DEVINTEX X DEMANDA'!A:E,5,0)<0,0,VLOOKUP(C804,'EST_DEVINTEX X DEMANDA'!A:E,5,0)),0) -> 3462 | U804: =T804*G804 -> 0 | V804: =U804/H804 -> 0 | W804: NÃO | X804: SIM | Y804: =(PLANEJAMENTO[[#This Row],[AGUARDANDO SEPARAÇÃO]]+PLANEJAMENTO[[#This Row],[FINALIZADO]])/(PLANEJAMENTO[[#This Row],[KIT]]+PLANEJAMENTO[[#This Row],[TOTAL LISTA]]) -> 1
A805: MELI_01 | B805: MERCADO LIVRE | C805: 34794 | D805: Condicionador Cachos Super Óleos | Salon Line SOS Cachos | E805: =VLOOKUP(PLANEJAMENTO[[#This Row],[SKU]],BASE!A:B,2,0) -> B | F805: ATIVO | G805: =VLOOKUP(PLANEJAMENTO[[#This Row],[SKU]],BASE!A:D,4,0) -> 1560 | H805: =VLOOKUP(PLANEJAMENTO[[#This Row],[SKU]],BASE!A:E,5,0) -> 12 | I805: =SUMIFS(IN_TRANSITO!E:E,IN_TRANSITO!B:B,PLANEJAMENTO!C805,IN_TRANSITO!H:H,PLANEJAMENTO!$I$2,IN_TRANSITO!W:W,PLANEJAMENTO!A805) -> 0 | J805: =SUMIFS(IN_TRANSITO!E:E,IN_TRANSITO!B:B,PLANEJAMENTO!C805,IN_TRANSITO!H:H,PLANEJAMENTO!$J$2,IN_TRANSITO!W:W,PLANEJAMENTO!A805) -> 0 | K805: =SUMIFS(PRODUCAO_SHRINK!E:E,PRODUCAO_SHRINK!B:B,PLANEJAMENTO[[#This Row],[SKU]],PRODUCAO_SHRINK!H:H,PLANEJAMENTO[[#Headers],[SHERINK SOLICITADO]],PRODUCAO_SHRINK!V:V,PLANEJAMENTO[[#This Row],[LISTA]]) -> 0 | L805: =SUMIFS(PRODUCAO_SHRINK!E:E,PRODUCAO_SHRINK!B:B,PLANEJAMENTO[[#This Row],[SKU]],PRODUCAO_SHRINK!H:H,PLANEJAMENTO[[#Headers],[SHERINK ENVIADO]],PRODUCAO_SHRINK!V:V,PLANEJAMENTO[[#This Row],[LISTA]]) -> 0 | M805: =SUMIFS(IN_TRANSITO!E:E,IN_TRANSITO!B:B,PLANEJAMENTO!C805,IN_TRANSITO!H:H,PLANEJAMENTO!$M$2,IN_TRANSITO!W:W,PLANEJAMENTO!A805) -> 63 | N805: 63 | O805: 0 | P805: =(PLANEJAMENTO[[#This Row],[AGUARDANDO SEPARAÇÃO]]+PLANEJAMENTO[[#This Row],[FINALIZADO]])-(PLANEJAMENTO[[#This Row],[TOTAL LISTA]]+PLANEJAMENTO[[#This Row],[KIT]]) -> 0 | Q805: =IFERROR(VLOOKUP(PLANEJAMENTO[[#This Row],[SKU]],EST_MERCOCAMP!A:E,5,0),0) -> 2040 | R805: =IFERROR(VLOOKUP(PLANEJAMENTO[[#This Row],[SKU]],EST_LMX!A:C,3,0),0) -> 2028 | S805: =IFERROR(IF(VLOOKUP(C805,'EST_DEVINTEX X DEMANDA'!A:E,5,0)<0,0,VLOOKUP(C805,'EST_DEVINTEX X DEMANDA'!A:E,5,0)),0) -> 3564 | U805: =T805*G805 -> 0 | V805: =U805/H805 -> 0 | W805: NÃO | X805: SIM | Y805: =(PLANEJAMENTO[[#This Row],[AGUARDANDO SEPARAÇÃO]]+PLANEJAMENTO[[#This Row],[FINALIZADO]])/(PLANEJAMENTO[[#This Row],[KIT]]+PLANEJAMENTO[[#This Row],[TOTAL LISTA]]) -> 1
A806: MELI_01 | B806: MERCADO LIVRE | C806: 34665 | D806: Ativador de Cachos Salon Line Super Óleos 500ml | S.O.S Cachos | E806: =VLOOKUP(PLANEJAMENTO[[#This Row],[SKU]],BASE!A:B,2,0) -> A | F806: ATIVO | G806: =VLOOKUP(PLANEJAMENTO[[#This Row],[SKU]],BASE!A:D,4,0) -> 936 | H806: =VLOOKUP(PLANEJAMENTO[[#This Row],[SKU]],BASE!A:E,5,0) -> 6 | I806: =SUMIFS(IN_TRANSITO!E:E,IN_TRANSITO!B:B,PLANEJAMENTO!C806,IN_TRANSITO!H:H,PLANEJAMENTO!$I$2,IN_TRANSITO!W:W,PLANEJAMENTO!A806) -> 0 | J806: =SUMIFS(IN_TRANSITO!E:E,IN_TRANSITO!B:B,PLANEJAMENTO!C806,IN_TRANSITO!H:H,PLANEJAMENTO!$J$2,IN_TRANSITO!W:W,PLANEJAMENTO!A806) -> 0 | K806: =SUMIFS(PRODUCAO_SHRINK!E:E,PRODUCAO_SHRINK!B:B,PLANEJAMENTO[[#This Row],[SKU]],PRODUCAO_SHRINK!H:H,PLANEJAMENTO[[#Headers],[SHERINK SOLICITADO]],PRODUCAO_SHRINK!V:V,PLANEJAMENTO[[#This Row],[LISTA]]) -> 0 | L806: =SUMIFS(PRODUCAO_SHRINK!E:E,PRODUCAO_SHRINK!B:B,PLANEJAMENTO[[#This Row],[SKU]],PRODUCAO_SHRINK!H:H,PLANEJAMENTO[[#Headers],[SHERINK ENVIADO]],PRODUCAO_SHRINK!V:V,PLANEJAMENTO[[#This Row],[LISTA]]) -> 0 | M806: =SUMIFS(IN_TRANSITO!E:E,IN_TRANSITO!B:B,PLANEJAMENTO!C806,IN_TRANSITO!H:H,PLANEJAMENTO!$M$2,IN_TRANSITO!W:W,PLANEJAMENTO!A806) -> 63 | N806: 63 | O806: 0 | P806: =(PLANEJAMENTO[[#This Row],[AGUARDANDO SEPARAÇÃO]]+PLANEJAMENTO[[#This Row],[FINALIZADO]])-(PLANEJAMENTO[[#This Row],[TOTAL LISTA]]+PLANEJAMENTO[[#This Row],[KIT]]) -> 0 | Q806: =IFERROR(VLOOKUP(PLANEJAMENTO[[#This Row],[SKU]],EST_MERCOCAMP!A:E,5,0),0) -> -1728 | R806: =IFERROR(VLOOKUP(PLANEJAMENTO[[#This Row],[SKU]],EST_LMX!A:C,3,0),0) -> 144 | S806: =IFERROR(IF(VLOOKUP(C806,'EST_DEVINTEX X DEMANDA'!A:E,5,0)<0,0,VLOOKUP(C806,'EST_DEVINTEX X DEMANDA'!A:E,5,0)),0) -> 9426 | U806: =T806*G806 -> 0 | V806: =U806/H806 -> 0 | W806: NÃO | X806: SIM | Y806: =(PLANEJAMENTO[[#This Row],[AGUARDANDO SEPARAÇÃO]]+PLANEJAMENTO[[#This Row],[FINALIZADO]])/(PLANEJAMENTO[[#This Row],[KIT]]+PLANEJAMENTO[[#This Row],[TOTAL LISTA]]) -> 1
A807: MELI_01 | B807: MERCADO LIVRE | C807: 34793 | D807: Shampoo Nutritivo SOS Cachos Super Óleos 300ml | Salon Line | E807: =VLOOKUP(PLANEJAMENTO[[#This Row],[SKU]],BASE!A:B,2,0) -> A | F807: ATIVO | G807: =VLOOKUP(PLANEJAMENTO[[#This Row],[SKU]],BASE!A:D,4,0) -> 1560 | H807: =VLOOKUP(PLANEJAMENTO[[#This Row],[SKU]],BASE!A:E,5,0) -> 12 | I807: =SUMIFS(IN_TRANSITO!E:E,IN_TRANSITO!B:B,PLANEJAMENTO!C807,IN_TRANSITO!H:H,PLANEJAMENTO!$I$2,IN_TRANSITO!W:W,PLANEJAMENTO!A807) -> 0 | J807: =SUMIFS(IN_TRANSITO!E:E,IN_TRANSITO!B:B,PLANEJAMENTO!C807,IN_TRANSITO!H:H,PLANEJAMENTO!$J$2,IN_TRANSITO!W:W,PLANEJAMENTO!A807) -> 0 | K807: =SUMIFS(PRODUCAO_SHRINK!E:E,PRODUCAO_SHRINK!B:B,PLANEJAMENTO[[#This Row],[SKU]],PRODUCAO_SHRINK!H:H,PLANEJAMENTO[[#Headers],[SHERINK SOLICITADO]],PRODUCAO_SHRINK!V:V,PLANEJAMENTO[[#This Row],[LISTA]]) -> 0 | L807: =SUMIFS(PRODUCAO_SHRINK!E:E,PRODUCAO_SHRINK!B:B,PLANEJAMENTO[[#This Row],[SKU]],PRODUCAO_SHRINK!H:H,PLANEJAMENTO[[#Headers],[SHERINK ENVIADO]],PRODUCAO_SHRINK!V:V,PLANEJAMENTO[[#This Row],[LISTA]]) -> 0 | M807: =SUMIFS(IN_TRANSITO!E:E,IN_TRANSITO!B:B,PLANEJAMENTO!C807,IN_TRANSITO!H:H,PLANEJAMENTO!$M$2,IN_TRANSITO!W:W,PLANEJAMENTO!A807) -> 63 | N807: 63 | O807: 0 | P807: =(PLANEJAMENTO[[#This Row],[AGUARDANDO SEPARAÇÃO]]+PLANEJAMENTO[[#This Row],[FINALIZADO]])-(PLANEJAMENTO[[#This Row],[TOTAL LISTA]]+PLANEJAMENTO[[#This Row],[KIT]]) -> 0 | Q807: =IFERROR(VLOOKUP(PLANEJAMENTO[[#This Row],[SKU]],EST_MERCOCAMP!A:E,5,0),0) -> 480 | R807: =IFERROR(VLOOKUP(PLANEJAMENTO[[#This Row],[SKU]],EST_LMX!A:C,3,0),0) -> 2208 | S807: =IFERROR(IF(VLOOKUP(C807,'EST_DEVINTEX X DEMANDA'!A:E,5,0)<0,0,VLOOKUP(C807,'EST_DEVINTEX X DEMANDA'!A:E,5,0)),0) -> 0 | U807: =T807*G807 -> 0 | V807: =U807/H807 -> 0 | W807: NÃO | X807: SIM | Y807: =(PLANEJAMENTO[[#This Row],[AGUARDANDO SEPARAÇÃO]]+PLANEJAMENTO[[#This Row],[FINALIZADO]])/(PLANEJAMENTO[[#This Row],[KIT]]+PLANEJAMENTO[[#This Row],[TOTAL LISTA]]) -> 1
A808: MELI_01 | B808: MERCADO LIVRE | C808: 34847 | D808: Cremascara 2 Em 1 S.O.S Cachos Super Oleos 1kg Salon Line | E808: =VLOOKUP(PLANEJAMENTO[[#This Row],[SKU]],BASE!A:B,2,0) -> B | F808: ATIVO | G808: =VLOOKUP(PLANEJAMENTO[[#This Row],[SKU]],BASE!A:D,4,0) -> 390 | H808: =VLOOKUP(PLANEJAMENTO[[#This Row],[SKU]],BASE!A:E,5,0) -> 6 | I808: =SUMIFS(IN_TRANSITO!E:E,IN_TRANSITO!B:B,PLANEJAMENTO!C808,IN_TRANSITO!H:H,PLANEJAMENTO!$I$2,IN_TRANSITO!W:W,PLANEJAMENTO!A808) -> 0 | J808: =SUMIFS(IN_TRANSITO!E:E,IN_TRANSITO!B:B,PLANEJAMENTO!C808,IN_TRANSITO!H:H,PLANEJAMENTO!$J$2,IN_TRANSITO!W:W,PLANEJAMENTO!A808) -> 0 | K808: =SUMIFS(PRODUCAO_SHRINK!E:E,PRODUCAO_SHRINK!B:B,PLANEJAMENTO[[#This Row],[SKU]],PRODUCAO_SHRINK!H:H,PLANEJAMENTO[[#Headers],[SHERINK SOLICITADO]],PRODUCAO_SHRINK!V:V,PLANEJAMENTO[[#This Row],[LISTA]]) -> 102 | L808: =SUMIFS(PRODUCAO_SHRINK!E:E,PRODUCAO_SHRINK!B:B,PLANEJAMENTO[[#This Row],[SKU]],PRODUCAO_SHRINK!H:H,PLANEJAMENTO[[#Headers],[SHERINK ENVIADO]],PRODUCAO_SHRINK!V:V,PLANEJAMENTO[[#This Row],[LISTA]]) -> 0 | M808: =SUMIFS(IN_TRANSITO!E:E,IN_TRANSITO!B:B,PLANEJAMENTO!C808,IN_TRANSITO!H:H,PLANEJAMENTO!$M$2,IN_TRANSITO!W:W,PLANEJAMENTO!A808) -> 63 | N808: 63 | O808: 102 | P808: =(PLANEJAMENTO[[#This Row],[AGUARDANDO SEPARAÇÃO]]+PLANEJAMENTO[[#This Row],[FINALIZADO]])-(PLANEJAMENTO[[#This Row],[TOTAL LISTA]]+PLANEJAMENTO[[#This Row],[KIT]]) -> -102 | Q808: =IFERROR(VLOOKUP(PLANEJAMENTO[[#This Row],[SKU]],EST_MERCOCAMP!A:E,5,0),0) -> -60 | R808: =IFERROR(VLOOKUP(PLANEJAMENTO[[#This Row],[SKU]],EST_LMX!A:C,3,0),0) -> 396 | S808: =IFERROR(IF(VLOOKUP(C808,'EST_DEVINTEX X DEMANDA'!A:E,5,0)<0,0,VLOOKUP(C808,'EST_DEVINTEX X DEMANDA'!A:E,5,0)),0) -> 0 | U808: =T808*G808 -> 0 | V808: =U808/H808 -> 0 | W808: SIM | X808: SIM | Y808: =(PLANEJAMENTO[[#This Row],[AGUARDANDO SEPARAÇÃO]]+PLANEJAMENTO[[#This Row],[FINALIZADO]])/(PLANEJAMENTO[[#This Row],[KIT]]+PLANEJAMENTO[[#This Row],[TOTAL LISTA]]) -> 0.38181818
A809: MELI_01 | B809: MERCADO LIVRE | C809: 32137 | D809: Oleo De Tratamento Super Oleos S.O.S Cachos 42ml Salon Line | E809: =VLOOKUP(PLANEJAMENTO[[#This Row],[SKU]],BASE!A:B,2,0) -> A | F809: ATIVO | G809: =VLOOKUP(PLANEJAMENTO[[#This Row],[SKU]],BASE!A:D,4,0) -> 8544 | H809: =VLOOKUP(PLANEJAMENTO[[#This Row],[SKU]],BASE!A:E,5,0) -> 12 | I809: =SUMIFS(IN_TRANSITO!E:E,IN_TRANSITO!B:B,PLANEJAMENTO!C809,IN_TRANSITO!H:H,PLANEJAMENTO!$I$2,IN_TRANSITO!W:W,PLANEJAMENTO!A809) -> 0 | J809: =SUMIFS(IN_TRANSITO!E:E,IN_TRANSITO!B:B,PLANEJAMENTO!C809,IN_TRANSITO!H:H,PLANEJAMENTO!$J$2,IN_TRANSITO!W:W,PLANEJAMENTO!A809) -> 0 | K809: =SUMIFS(PRODUCAO_SHRINK!E:E,PRODUCAO_SHRINK!B:B,PLANEJAMENTO[[#This Row],[SKU]],PRODUCAO_SHRINK!H:H,PLANEJAMENTO[[#Headers],[SHERINK SOLICITADO]],PRODUCAO_SHRINK!V:V,PLANEJAMENTO[[#This Row],[LISTA]]) -> 0 | L809: =SUMIFS(PRODUCAO_SHRINK!E:E,PRODUCAO_SHRINK!B:B,PLANEJAMENTO[[#This Row],[SKU]],PRODUCAO_SHRINK!H:H,PLANEJAMENTO[[#Headers],[SHERINK ENVIADO]],PRODUCAO_SHRINK!V:V,PLANEJAMENTO[[#This Row],[LISTA]]) -> 0 | M809: =SUMIFS(IN_TRANSITO!E:E,IN_TRANSITO!B:B,PLANEJAMENTO!C809,IN_TRANSITO!H:H,PLANEJAMENTO!$M$2,IN_TRANSITO!W:W,PLANEJAMENTO!A809) -> 1335 | N809: 63 | O809: 1272 | P809: =(PLANEJAMENTO[[#This Row],[AGUARDANDO SEPARAÇÃO]]+PLANEJAMENTO[[#This Row],[FINALIZADO]])-(PLANEJAMENTO[[#This Row],[TOTAL LISTA]]+PLANEJAMENTO[[#This Row],[KIT]]) -> 0 | Q809: =IFERROR(VLOOKUP(PLANEJAMENTO[[#This Row],[SKU]],EST_MERCOCAMP!A:E,5,0),0) -> 11244 | R809: =IFERROR(VLOOKUP(PLANEJAMENTO[[#This Row],[SKU]],EST_LMX!A:C,3,0),0) -> 11646 | S809: =IFERROR(IF(VLOOKUP(C809,'EST_DEVINTEX X DEMANDA'!A:E,5,0)<0,0,VLOOKUP(C809,'EST_DEVINTEX X DEMANDA'!A:E,5,0)),0) -> 29904 | U809: =T809*G809 -> 0 | V809: =U809/H809 -> 0 | W809: NÃO | X809: SIM | Y809: =(PLANEJAMENTO[[#This Row],[AGUARDANDO SEPARAÇÃO]]+PLANEJAMENTO[[#This Row],[FINALIZADO]])/(PLANEJAMENTO[[#This Row],[KIT]]+PLANEJAMENTO[[#This Row],[TOTAL LISTA]]) -> 1
A810: MELI_01 | B810: MERCADO LIVRE | C810: 95701 | D810: Creme Para Pentear Definicao Maxima 1kg - Salon Line | E810: =VLOOKUP(PLANEJAMENTO[[#This Row],[SKU]],BASE!A:B,2,0) -> A | F810: ATIVO | G810: =VLOOKUP(PLANEJAMENTO[[#This Row],[SKU]],BASE!A:D,4,0) -> 480 | H810: =VLOOKUP(PLANEJAMENTO[[#This Row],[SKU]],BASE!A:E,5,0) -> 6 | I810: =SUMIFS(IN_TRANSITO!E:E,IN_TRANSITO!B:B,PLANEJAMENTO!C810,IN_TRANSITO!H:H,PLANEJAMENTO!$I$2,IN_TRANSITO!W:W,PLANEJAMENTO!A810) -> 0 | J810: =SUMIFS(IN_TRANSITO!E:E,IN_TRANSITO!B:B,PLANEJAMENTO!C810,IN_TRANSITO!H:H,PLANEJAMENTO!$J$2,IN_TRANSITO!W:W,PLANEJAMENTO!A810) -> 0 | K810: =SUMIFS(PRODUCAO_SHRINK!E:E,PRODUCAO_SHRINK!B:B,PLANEJAMENTO[[#This Row],[SKU]],PRODUCAO_SHRINK!H:H,PLANEJAMENTO[[#Headers],[SHERINK SOLICITADO]],PRODUCAO_SHRINK!V:V,PLANEJAMENTO[[#This Row],[LISTA]]) -> 42 | L810: =SUMIFS(PRODUCAO_SHRINK!E:E,PRODUCAO_SHRINK!B:B,PLANEJAMENTO[[#This Row],[SKU]],PRODUCAO_SHRINK!H:H,PLANEJAMENTO[[#Headers],[SHERINK ENVIADO]],PRODUCAO_SHRINK!V:V,PLANEJAMENTO[[#This Row],[LISTA]]) -> 0 | M810: =SUMIFS(IN_TRANSITO!E:E,IN_TRANSITO!B:B,PLANEJAMENTO!C810,IN_TRANSITO!H:H,PLANEJAMENTO!$M$2,IN_TRANSITO!W:W,PLANEJAMENTO!A810) -> 329 | N810: 329 | O810: 42 | P810: =(PLANEJAMENTO[[#This Row],[AGUARDANDO SEPARAÇÃO]]+PLANEJAMENTO[[#This Row],[FINALIZADO]])-(PLANEJAMENTO[[#This Row],[TOTAL LISTA]]+PLANEJAMENTO[[#This Row],[KIT]]) -> -42 | Q810: =IFERROR(VLOOKUP(PLANEJAMENTO[[#This Row],[SKU]],EST_MERCOCAMP!A:E,5,0),0) -> -3960 | R810: =IFERROR(VLOOKUP(PLANEJAMENTO[[#This Row],[SKU]],EST_LMX!A:C,3,0),0) -> 2148 | S810: =IFERROR(IF(VLOOKUP(C810,'EST_DEVINTEX X DEMANDA'!A:E,5,0)<0,0,VLOOKUP(C810,'EST_DEVINTEX X DEMANDA'!A:E,5,0)),0) -> 7920 | U810: =T810*G810 -> 0 | V810: =U810/H810 -> 0 | W810: SIM | X810: SIM | Y810: =(PLANEJAMENTO[[#This Row],[AGUARDANDO SEPARAÇÃO]]+PLANEJAMENTO[[#This Row],[FINALIZADO]])/(PLANEJAMENTO[[#This Row],[KIT]]+PLANEJAMENTO[[#This Row],[TOTAL LISTA]]) -> 0.88679245
A811: MELI_01 | B811: MERCADO LIVRE | C811: 32920 | D811: Creme Pentear Oleo Extraordinario Uva + Melancia Salon Line | E811: =VLOOKUP(PLANEJAMENTO[[#This Row],[SKU]],BASE!A:B,2,0) -> A | F811: ATIVO | G811: =VLOOKUP(PLANEJAMENTO[[#This Row],[SKU]],BASE!A:D,4,0) -> 480 | H811: =VLOOKUP(PLANEJAMENTO[[#This Row],[SKU]],BASE!A:E,5,0) -> 6 | I811: =SUMIFS(IN_TRANSITO!E:E,IN_TRANSITO!B:B,PLANEJAMENTO!C811,IN_TRANSITO!H:H,PLANEJAMENTO!$I$2,IN_TRANSITO!W:W,PLANEJAMENTO!A811) -> 0 | J811: =SUMIFS(IN_TRANSITO!E:E,IN_TRANSITO!B:B,PLANEJAMENTO!C811,IN_TRANSITO!H:H,PLANEJAMENTO!$J$2,IN_TRANSITO!W:W,PLANEJAMENTO!A811) -> 0 | K811: =SUMIFS(PRODUCAO_SHRINK!E:E,PRODUCAO_SHRINK!B:B,PLANEJAMENTO[[#This Row],[SKU]],PRODUCAO_SHRINK!H:H,PLANEJAMENTO[[#Headers],[SHERINK SOLICITADO]],PRODUCAO_SHRINK!V:V,PLANEJAMENTO[[#This Row],[LISTA]]) -> 0 | L811: =SUMIFS(PRODUCAO_SHRINK!E:E,PRODUCAO_SHRINK!B:B,PLANEJAMENTO[[#This Row],[SKU]],PRODUCAO_SHRINK!H:H,PLANEJAMENTO[[#Headers],[SHERINK ENVIADO]],PRODUCAO_SHRINK!V:V,PLANEJAMENTO[[#This Row],[LISTA]]) -> 432 | M811: =SUMIFS(IN_TRANSITO!E:E,IN_TRANSITO!B:B,PLANEJAMENTO!C811,IN_TRANSITO!H:H,PLANEJAMENTO!$M$2,IN_TRANSITO!W:W,PLANEJAMENTO!A811) -> 329 | N811: 329 | O811: 432 | P811: =(PLANEJAMENTO[[#This Row],[AGUARDANDO SEPARAÇÃO]]+PLANEJAMENTO[[#This Row],[FINALIZADO]])-(PLANEJAMENTO[[#This Row],[TOTAL LISTA]]+PLANEJAMENTO[[#This Row],[KIT]]) -> -432 | Q811: =IFERROR(VLOOKUP(PLANEJAMENTO[[#This Row],[SKU]],EST_MERCOCAMP!A:E,5,0),0) -> 4158 | R811: =IFERROR(VLOOKUP(PLANEJAMENTO[[#This Row],[SKU]],EST_LMX!A:C,3,0),0) -> 384 | S811: =IFERROR(IF(VLOOKUP(C811,'EST_DEVINTEX X DEMANDA'!A:E,5,0)<0,0,VLOOKUP(C811,'EST_DEVINTEX X DEMANDA'!A:E,5,0)),0) -> 4800 | U811: =T811*G811 -> 0 | V811: =U811/H811 -> 0 | W811: NÃO | X811: SIM | Y811: =(PLANEJAMENTO[[#This Row],[AGUARDANDO SEPARAÇÃO]]+PLANEJAMENTO[[#This Row],[FINALIZADO]])/(PLANEJAMENTO[[#This Row],[KIT]]+PLANEJAMENTO[[#This Row],[TOTAL LISTA]]) -> 0.43232589
A812: MELI_01 | B812: MERCADO LIVRE | C812: 33095 | D812: CACHOS DOS SONHOS ÓLEO SÉRUM DEFINIÇÃO NATURAL MULTY 200ML | E812: =VLOOKUP(PLANEJAMENTO[[#This Row],[SKU]],BASE!A:B,2,0) -> A | F812: ATIVO | G812: =VLOOKUP(PLANEJAMENTO[[#This Row],[SKU]],BASE!A:D,4,0) -> 2484 | H812: =VLOOKUP(PLANEJAMENTO[[#This Row],[SKU]],BASE!A:E,5,0) -> 6 | I812: =SUMIFS(IN_TRANSITO!E:E,IN_TRANSITO!B:B,PLANEJAMENTO!C812,IN_TRANSITO!H:H,PLANEJAMENTO!$I$2,IN_TRANSITO!W:W,PLANEJAMENTO!A812) -> 558 | J812: =SUMIFS(IN_TRANSITO!E:E,IN_TRANSITO!B:B,PLANEJAMENTO!C812,IN_TRANSITO!H:H,PLANEJAMENTO!$J$2,IN_TRANSITO!W:W,PLANEJAMENTO!A812) -> 0 | K812: =SUMIFS(PRODUCAO_SHRINK!E:E,PRODUCAO_SHRINK!B:B,PLANEJAMENTO[[#This Row],[SKU]],PRODUCAO_SHRINK!H:H,PLANEJAMENTO[[#Headers],[SHERINK SOLICITADO]],PRODUCAO_SHRINK!V:V,PLANEJAMENTO[[#This Row],[LISTA]]) -> 0 | L812: =SUMIFS(PRODUCAO_SHRINK!E:E,PRODUCAO_SHRINK!B:B,PLANEJAMENTO[[#This Row],[SKU]],PRODUCAO_SHRINK!H:H,PLANEJAMENTO[[#Headers],[SHERINK ENVIADO]],PRODUCAO_SHRINK!V:V,PLANEJAMENTO[[#This Row],[LISTA]]) -> 0 | M812: =SUMIFS(IN_TRANSITO!E:E,IN_TRANSITO!B:B,PLANEJAMENTO!C812,IN_TRANSITO!H:H,PLANEJAMENTO!$M$2,IN_TRANSITO!W:W,PLANEJAMENTO!A812) -> 0 | N812: 1960 | O812: 558 | P812: =(PLANEJAMENTO[[#This Row],[AGUARDANDO SEPARAÇÃO]]+PLANEJAMENTO[[#This Row],[FINALIZADO]])-(PLANEJAMENTO[[#This Row],[TOTAL LISTA]]+PLANEJAMENTO[[#This Row],[KIT]]) -> -1960 | Q812: =IFERROR(VLOOKUP(PLANEJAMENTO[[#This Row],[SKU]],EST_MERCOCAMP!A:E,5,0),0) -> -4974 | R812: =IFERROR(VLOOKUP(PLANEJAMENTO[[#This Row],[SKU]],EST_LMX!A:C,3,0),0) -> 0 | S812: =IFERROR(IF(VLOOKUP(C812,'EST_DEVINTEX X DEMANDA'!A:E,5,0)<0,0,VLOOKUP(C812,'EST_DEVINTEX X DEMANDA'!A:E,5,0)),0) -> 11298 | U812: =T812*G812 -> 0 | V812: =U812/H812 -> 0 | W812: NÃO | X812: SIM | Y812: =(PLANEJAMENTO[[#This Row],[AGUARDANDO SEPARAÇÃO]]+PLANEJAMENTO[[#This Row],[FINALIZADO]])/(PLANEJAMENTO[[#This Row],[KIT]]+PLANEJAMENTO[[#This Row],[TOTAL LISTA]]) -> 0.22160445
A813: MELI_01 | B813: MERCADO LIVRE | C813: 33107 | D813: Gelatina #Todecacho Definicao Natural 550g Salon Line | E813: =VLOOKUP(PLANEJAMENTO[[#This Row],[SKU]],BASE!A:B,2,0) -> A | F813: ATIVO | G813: =VLOOKUP(PLANEJAMENTO[[#This Row],[SKU]],BASE!A:D,4,0) -> 960 | H813: =VLOOKUP(PLANEJAMENTO[[#This Row],[SKU]],BASE!A:E,5,0) -> 6 | I813: =SUMIFS(IN_TRANSITO!E:E,IN_TRANSITO!B:B,PLANEJAMENTO!C813,IN_TRANSITO!H:H,PLANEJAMENTO!$I$2,IN_TRANSITO!W:W,PLANEJAMENTO!A813) -> 0 | J813: =SUMIFS(IN_TRANSITO!E:E,IN_TRANSITO!B:B,PLANEJAMENTO!C813,IN_TRANSITO!H:H,PLANEJAMENTO!$J$2,IN_TRANSITO!W:W,PLANEJAMENTO!A813) -> 0 | K813: =SUMIFS(PRODUCAO_SHRINK!E:E,PRODUCAO_SHRINK!B:B,PLANEJAMENTO[[#This Row],[SKU]],PRODUCAO_SHRINK!H:H,PLANEJAMENTO[[#Headers],[SHERINK SOLICITADO]],PRODUCAO_SHRINK!V:V,PLANEJAMENTO[[#This Row],[LISTA]]) -> 1374 | L813: =SUMIFS(PRODUCAO_SHRINK!E:E,PRODUCAO_SHRINK!B:B,PLANEJAMENTO[[#This Row],[SKU]],PRODUCAO_SHRINK!H:H,PLANEJAMENTO[[#Headers],[SHERINK ENVIADO]],PRODUCAO_SHRINK!V:V,PLANEJAMENTO[[#This Row],[LISTA]]) -> 0 | M813: =SUMIFS(IN_TRANSITO!E:E,IN_TRANSITO!B:B,PLANEJAMENTO!C813,IN_TRANSITO!H:H,PLANEJAMENTO!$M$2,IN_TRANSITO!W:W,PLANEJAMENTO!A813) -> 0 | N813: 1960 | O813: 1374 | P813: =(PLANEJAMENTO[[#This Row],[AGUARDANDO SEPARAÇÃO]]+PLANEJAMENTO[[#This Row],[FINALIZADO]])-(PLANEJAMENTO[[#This Row],[TOTAL LISTA]]+PLANEJAMENTO[[#This Row],[KIT]]) -> -3334 | Q813: =IFERROR(VLOOKUP(PLANEJAMENTO[[#This Row],[SKU]],EST_MERCOCAMP!A:E,5,0),0) -> 20178 | R813: =IFERROR(VLOOKUP(PLANEJAMENTO[[#This Row],[SKU]],EST_LMX!A:C,3,0),0) -> 9174 | S813: =IFERROR(IF(VLOOKUP(C813,'EST_DEVINTEX X DEMANDA'!A:E,5,0)<0,0,VLOOKUP(C813,'EST_DEVINTEX X DEMANDA'!A:E,5,0)),0) -> 19320 | U813: =T813*G813 -> 0 | V813: =U813/H813 -> 0 | W813: SIM | X813: SIM | Y813: =(PLANEJAMENTO[[#This Row],[AGUARDANDO SEPARAÇÃO]]+PLANEJAMENTO[[#This Row],[FINALIZADO]])/(PLANEJAMENTO[[#This Row],[KIT]]+PLANEJAMENTO[[#This Row],[TOTAL LISTA]]) -> 0
A814: MELI_01 | B814: MERCADO LIVRE | C814: 32060 | D814: Creme Para Pentear Definicao Natural Salon Line Cachos 1kg | E814: =VLOOKUP(PLANEJAMENTO[[#This Row],[SKU]],BASE!A:B,2,0) -> A | F814: ATIVO | G814: =VLOOKUP(PLANEJAMENTO[[#This Row],[SKU]],BASE!A:D,4,0) -> 480 | H814: =VLOOKUP(PLANEJAMENTO[[#This Row],[SKU]],BASE!A:E,5,0) -> 6 | I814: =SUMIFS(IN_TRANSITO!E:E,IN_TRANSITO!B:B,PLANEJAMENTO!C814,IN_TRANSITO!H:H,PLANEJAMENTO!$I$2,IN_TRANSITO!W:W,PLANEJAMENTO!A814) -> 0 | J814: =SUMIFS(IN_TRANSITO!E:E,IN_TRANSITO!B:B,PLANEJAMENTO!C814,IN_TRANSITO!H:H,PLANEJAMENTO!$J$2,IN_TRANSITO!W:W,PLANEJAMENTO!A814) -> 0 | K814: =SUMIFS(PRODUCAO_SHRINK!E:E,PRODUCAO_SHRINK!B:B,PLANEJAMENTO[[#This Row],[SKU]],PRODUCAO_SHRINK!H:H,PLANEJAMENTO[[#Headers],[SHERINK SOLICITADO]],PRODUCAO_SHRINK!V:V,PLANEJAMENTO[[#This Row],[LISTA]]) -> 6414 | L814: =SUMIFS(PRODUCAO_SHRINK!E:E,PRODUCAO_SHRINK!B:B,PLANEJAMENTO[[#This Row],[SKU]],PRODUCAO_SHRINK!H:H,PLANEJAMENTO[[#Headers],[SHERINK ENVIADO]],PRODUCAO_SHRINK!V:V,PLANEJAMENTO[[#This Row],[LISTA]]) -> 0 | M814: =SUMIFS(IN_TRANSITO!E:E,IN_TRANSITO!B:B,PLANEJAMENTO!C814,IN_TRANSITO!H:H,PLANEJAMENTO!$M$2,IN_TRANSITO!W:W,PLANEJAMENTO!A814) -> 2087 | N814: 2289 | O814: 8172 | P814: =(PLANEJAMENTO[[#This Row],[AGUARDANDO SEPARAÇÃO]]+PLANEJAMENTO[[#This Row],[FINALIZADO]])-(PLANEJAMENTO[[#This Row],[TOTAL LISTA]]+PLANEJAMENTO[[#This Row],[KIT]]) -> -8374 | Q814: =IFERROR(VLOOKUP(PLANEJAMENTO[[#This Row],[SKU]],EST_MERCOCAMP!A:E,5,0),0) -> 19698 | R814: =IFERROR(VLOOKUP(PLANEJAMENTO[[#This Row],[SKU]],EST_LMX!A:C,3,0),0) -> 11174 | S814: =IFERROR(IF(VLOOKUP(C814,'EST_DEVINTEX X DEMANDA'!A:E,5,0)<0,0,VLOOKUP(C814,'EST_DEVINTEX X DEMANDA'!A:E,5,0)),0) -> 58446 | U814: =T814*G814 -> 0 | V814: =U814/H814 -> 0 | W814: SIM | X814: SIM | Y814: =(PLANEJAMENTO[[#This Row],[AGUARDANDO SEPARAÇÃO]]+PLANEJAMENTO[[#This Row],[FINALIZADO]])/(PLANEJAMENTO[[#This Row],[KIT]]+PLANEJAMENTO[[#This Row],[TOTAL LISTA]]) -> 0.19950292
A815: MELI_01 | B815: MERCADO LIVRE | C815: 32259 | D815: Salon Line Sos Cachos +Poderosos Oleo 10 Em 1 42ml | E815: =VLOOKUP(PLANEJAMENTO[[#This Row],[SKU]],BASE!A:B,2,0) -> A | F815: ATIVO | G815: =VLOOKUP(PLANEJAMENTO[[#This Row],[SKU]],BASE!A:D,4,0) -> 8544 | H815: =VLOOKUP(PLANEJAMENTO[[#This Row],[SKU]],BASE!A:E,5,0) -> 12 | I815: =SUMIFS(IN_TRANSITO!E:E,IN_TRANSITO!B:B,PLANEJAMENTO!C815,IN_TRANSITO!H:H,PLANEJAMENTO!$I$2,IN_TRANSITO!W:W,PLANEJAMENTO!A815) -> 0 | J815: =SUMIFS(IN_TRANSITO!E:E,IN_TRANSITO!B:B,PLANEJAMENTO!C815,IN_TRANSITO!H:H,PLANEJAMENTO!$J$2,IN_TRANSITO!W:W,PLANEJAMENTO!A815) -> 0 | K815: =SUMIFS(PRODUCAO_SHRINK!E:E,PRODUCAO_SHRINK!B:B,PLANEJAMENTO[[#This Row],[SKU]],PRODUCAO_SHRINK!H:H,PLANEJAMENTO[[#Headers],[SHERINK SOLICITADO]],PRODUCAO_SHRINK!V:V,PLANEJAMENTO[[#This Row],[LISTA]]) -> 0 | L815: =SUMIFS(PRODUCAO_SHRINK!E:E,PRODUCAO_SHRINK!B:B,PLANEJAMENTO[[#This Row],[SKU]],PRODUCAO_SHRINK!H:H,PLANEJAMENTO[[#Headers],[SHERINK ENVIADO]],PRODUCAO_SHRINK!V:V,PLANEJAMENTO[[#This Row],[LISTA]]) -> 0 | M815: =SUMIFS(IN_TRANSITO!E:E,IN_TRANSITO!B:B,PLANEJAMENTO!C815,IN_TRANSITO!H:H,PLANEJAMENTO!$M$2,IN_TRANSITO!W:W,PLANEJAMENTO!A815) -> 24 | N815: 0 | O815: 24 | P815: =(PLANEJAMENTO[[#This Row],[AGUARDANDO SEPARAÇÃO]]+PLANEJAMENTO[[#This Row],[FINALIZADO]])-(PLANEJAMENTO[[#This Row],[TOTAL LISTA]]+PLANEJAMENTO[[#This Row],[KIT]]) -> 0 | Q815: =IFERROR(VLOOKUP(PLANEJAMENTO[[#This Row],[SKU]],EST_MERCOCAMP!A:E,5,0),0) -> 21780 | R815: =IFERROR(VLOOKUP(PLANEJAMENTO[[#This Row],[SKU]],EST_LMX!A:C,3,0),0) -> 978 | S815: =IFERROR(IF(VLOOKUP(C815,'EST_DEVINTEX X DEMANDA'!A:E,5,0)<0,0,VLOOKUP(C815,'EST_DEVINTEX X DEMANDA'!A:E,5,0)),0) -> 24348 | U815: =T815*G815 -> 0 | V815: =U815/H815 -> 0 | W815: NÃO | X815: NÃO | Y815: =(PLANEJAMENTO[[#This Row],[AGUARDANDO SEPARAÇÃO]]+PLANEJAMENTO[[#This Row],[FINALIZADO]])/(PLANEJAMENTO[[#This Row],[KIT]]+PLANEJAMENTO[[#This Row],[TOTAL LISTA]]) -> 1
... A836: MELI_01 | B836: MERCADO LIVRE | C836: 32022 | D836: Salon Line Spray Defrizante Meu Liso Demais Protecao Termica 240ml | E836: =VLOOKUP(PLANEJAMENTO[[#This Row],[SKU]],BASE!A:B,2,0) -> B | F836: ATIVO | G836: =VLOOKUP(PLANEJAMENTO[[#This Row],[SKU]],BASE!A:D,4,0) -> 1584 | H836: =VLOOKUP(PLANEJAMENTO[[#This Row],[SKU]],BASE!A:E,5,0) -> 6 | I836: =SUMIFS(IN_TRANSITO!E:E,IN_TRANSITO!B:B,PLANEJAMENTO!C836,IN_TRANSITO!H:H,PLANEJAMENTO!$I$2,IN_TRANSITO!W:W,PLANEJAMENTO!A836) -> 0 | J836: =SUMIFS(IN_TRANSITO!E:E,IN_TRANSITO!B:B,PLANEJAMENTO!C836,IN_TRANSITO!H:H,PLANEJAMENTO!$J$2,IN_TRANSITO!W:W,PLANEJAMENTO!A836) -> 0 | K836: =SUMIFS(PRODUCAO_SHRINK!E:E,PRODUCAO_SHRINK!B:B,PLANEJAMENTO[[#This Row],[SKU]],PRODUCAO_SHRINK!H:H,PLANEJAMENTO[[#Headers],[SHERINK SOLICITADO]],PRODUCAO_SHRINK!V:V,PLANEJAMENTO[[#This Row],[LISTA]]) -> 0 | L836: =SUMIFS(PRODUCAO_SHRINK!E:E,PRODUCAO_SHRINK!B:B,PLANEJAMENTO[[#This Row],[SKU]],PRODUCAO_SHRINK!H:H,PLANEJAMENTO[[#Headers],[SHERINK ENVIADO]],PRODUCAO_SHRINK!V:V,PLANEJAMENTO[[#This Row],[LISTA]]) -> 0 | M836: =SUMIFS(IN_TRANSITO!E:E,IN_TRANSITO!B:B,PLANEJAMENTO!C836,IN_TRANSITO!H:H,PLANEJAMENTO!$M$2,IN_TRANSITO!W:W,PLANEJAMENTO!A836) -> 450 | N836: 0 | O836: 450 | P836: =(PLANEJAMENTO[[#This Row],[AGUARDANDO SEPARAÇÃO]]+PLANEJAMENTO[[#This Row],[FINALIZADO]])-(PLANEJAMENTO[[#This Row],[TOTAL LISTA]]+PLANEJAMENTO[[#This Row],[KIT]]) -> 0 | Q836: =IFERROR(VLOOKUP(PLANEJAMENTO[[#This Row],[SKU]],EST_MERCOCAMP!A:E,5,0),0) -> -384 | R836: =IFERROR(VLOOKUP(PLANEJAMENTO[[#This Row],[SKU]],EST_LMX!A:C,3,0),0) -> 1608 | S836: =IFERROR(IF(VLOOKUP(C836,'EST_DEVINTEX X DEMANDA'!A:E,5,0)<0,0,VLOOKUP(C836,'EST_DEVINTEX X DEMANDA'!A:E,5,0)),0) -> 16182 | U836: =T836*G836 -> 0 | V836: =U836/H836 -> 0 | W836: NÃO | X836: NÃO | Y836: =(PLANEJAMENTO[[#This Row],[AGUARDANDO SEPARAÇÃO]]+PLANEJAMENTO[[#This Row],[FINALIZADO]])/(PLANEJAMENTO[[#This Row],[KIT]]+PLANEJAMENTO[[#This Row],[TOTAL LISTA]]) -> 1
A837: MELI_01 | B837: MERCADO LIVRE | C837: 33452 | D837: Kit Shampoo 300ml + Creme Multifuncional Definicao Natural | E837: =VLOOKUP(PLANEJAMENTO[[#This Row],[SKU]],BASE!A:B,2,0) -> A | F837: ATIVO | G837: 504 | H837: =VLOOKUP(PLANEJAMENTO[[#This Row],[SKU]],BASE!A:E,5,0) -> 6 | I837: =SUMIFS(IN_TRANSITO!E:E,IN_TRANSITO!B:B,PLANEJAMENTO!C837,IN_TRANSITO!H:H,PLANEJAMENTO!$I$2,IN_TRANSITO!W:W,PLANEJAMENTO!A837) -> 0 | J837: =SUMIFS(IN_TRANSITO!E:E,IN_TRANSITO!B:B,PLANEJAMENTO!C837,IN_TRANSITO!H:H,PLANEJAMENTO!$J$2,IN_TRANSITO!W:W,PLANEJAMENTO!A837) -> 0 | K837: =SUMIFS(PRODUCAO_SHRINK!E:E,PRODUCAO_SHRINK!B:B,PLANEJAMENTO[[#This Row],[SKU]],PRODUCAO_SHRINK!H:H,PLANEJAMENTO[[#Headers],[SHERINK SOLICITADO]],PRODUCAO_SHRINK!V:V,PLANEJAMENTO[[#This Row],[LISTA]]) -> 0 | L837: =SUMIFS(PRODUCAO_SHRINK!E:E,PRODUCAO_SHRINK!B:B,PLANEJAMENTO[[#This Row],[SKU]],PRODUCAO_SHRINK!H:H,PLANEJAMENTO[[#Headers],[SHERINK ENVIADO]],PRODUCAO_SHRINK!V:V,PLANEJAMENTO[[#This Row],[LISTA]]) -> 0 | M837: =SUMIFS(IN_TRANSITO!E:E,IN_TRANSITO!B:B,PLANEJAMENTO!C837,IN_TRANSITO!H:H,PLANEJAMENTO!$M$2,IN_TRANSITO!W:W,PLANEJAMENTO!A837) -> 504 | N837: 0 | O837: 504 | P837: =(PLANEJAMENTO[[#This Row],[AGUARDANDO SEPARAÇÃO]]+PLANEJAMENTO[[#This Row],[FINALIZADO]])-(PLANEJAMENTO[[#This Row],[TOTAL LISTA]]+PLANEJAMENTO[[#This Row],[KIT]]) -> 0 | Q837: =IFERROR(VLOOKUP(PLANEJAMENTO[[#This Row],[SKU]],EST_MERCOCAMP!A:E,5,0),0) -> 162 | R837: =IFERROR(VLOOKUP(PLANEJAMENTO[[#This Row],[SKU]],EST_LMX!A:C,3,0),0) -> 118 | S837: =IFERROR(IF(VLOOKUP(C837,'EST_DEVINTEX X DEMANDA'!A:E,5,0)<0,0,VLOOKUP(C837,'EST_DEVINTEX X DEMANDA'!A:E,5,0)),0) -> 6300 | U837: =T837*G837 -> 0 | V837: =U837/H837 -> 0 | W837: NÃO | X837: NÃO | Y837: =(PLANEJAMENTO[[#This Row],[AGUARDANDO SEPARAÇÃO]]+PLANEJAMENTO[[#This Row],[FINALIZADO]])/(PLANEJAMENTO[[#This Row],[KIT]]+PLANEJAMENTO[[#This Row],[TOTAL LISTA]]) -> 1
